{
  "version": 8,
  "blockIdVersion": 11,
  "anchorX": 0,
  "anchorY": 0,
  "anchorZ": 0,
  "blocks": [
    {
      "x": -6,
      "y": 0,
      "z": -6,
      "name": "Soil_Dirt"
    },
    {
      "x": -6,
      "y": 1,
      "z": -6,
      "name": "Soil_Grass"
    },
    {
      "x": -6,
      "y": 0,
      "z": -5,
      "name": "Soil_Dirt"
    },
    {
      "x": -6,
      "y": 1,
      "z": -5,
      "name": "Soil_Grass"
    },
    {
      "x": -6,
      "y": 0,
      "z": -4,
      "name": "Soil_Dirt"
    },
    {
      "x": -6,
      "y": 1,
      "z": -4,
      "name": "Soil_Grass"
    },
    {
      "x": -6,
      "y": 2,
      "z": -4,
      "name": "Rock_Sandstone_White_Brick_Smooth_Half",
      "rotation": 7
    },
    {
      "x": -6,
      "y": 0,
      "z": -3,
      "name": "Soil_Dirt"
    },
    {
      "x": -6,
      "y": 1,
      "z": -3,
      "name": "Soil_Grass"
    },
    {
      "x": -6,
      "y": 2,
      "z": -3,
      "name": "Rock_Sandstone_White_Brick_Smooth_Half",
      "rotation": 7
    },
    {
      "x": -6,
      "y": 0,
      "z": -2,
      "name": "Soil_Dirt"
    },
    {
      "x": -6,
      "y": 1,
      "z": -2,
      "name": "Soil_Grass"
    },
    {
      "x": -6,
      "y": 2,
      "z": -2,
      "name": "Rock_Sandstone_White_Brick_Smooth_Half",
      "rotation": 7
    },
    {
      "x": -6,
      "y": 0,
      "z": -1,
      "name": "Soil_Dirt"
    },
    {
      "x": -6,
      "y": 1,
      "z": -1,
      "name": "Rock_Sandstone_White_Brick_Smooth"
    },
    {
      "x": -6,
      "y": 0,
      "z": 0,
      "name": "Soil_Dirt"
    },
    {
      "x": -6,
      "y": 1,
      "z": 0,
      "name": "Rock_Sandstone_White_Brick_Smooth"
    },
    {
      "x": -6,
      "y": 0,
      "z": 1,
      "name": "Soil_Dirt"
    },
    {
      "x": -6,
      "y": 1,
      "z": 1,
      "name": "Rock_Sandstone_White_Brick_Smooth"
    },
    {
      "x": -6,
      "y": 0,
      "z": 2,
      "name": "Soil_Dirt"
    },
    {
      "x": -6,
      "y": 1,
      "z": 2,
      "name": "Rock_Sandstone_White_Brick_Smooth"
    },
    {
      "x": -6,
      "y": 0,
      "z": 3,
      "name": "Soil_Dirt"
    },
    {
      "x": -6,
      "y": 1,
      "z": 3,
      "name": "Soil_Grass"
    },
    {
      "x": -6,
      "y": 2,
      "z": 3,
      "name": "Rock_Sandstone_White_Brick_Smooth_Half",
      "rotation": 7
    },
    {
      "x": -6,
      "y": 0,
      "z": 4,
      "name": "Soil_Dirt"
    },
    {
      "x": -6,
      "y": 1,
      "z": 4,
      "name": "Soil_Grass"
    },
    {
      "x": -6,
      "y": 2,
      "z": 4,
      "name": "Rock_Sandstone_White_Brick_Smooth_Half",
      "rotation": 7
    },
    {
      "x": -6,
      "y": 0,
      "z": 5,
      "name": "Soil_Dirt"
    },
    {
      "x": -6,
      "y": 1,
      "z": 5,
      "name": "Soil_Grass"
    },
    {
      "x": -6,
      "y": 2,
      "z": 5,
      "name": "Rock_Sandstone_White_Brick_Smooth_Half",
      "rotation": 7
    },
    {
      "x": -6,
      "y": 0,
      "z": 6,
      "name": "Soil_Dirt"
    },
    {
      "x": -6,
      "y": 1,
      "z": 6,
      "name": "Soil_Grass"
    },
    {
      "x": -6,
      "y": 0,
      "z": 7,
      "name": "Soil_Dirt"
    },
    {
      "x": -6,
      "y": 1,
      "z": 7,
      "name": "Soil_Grass"
    },
    {
      "x": -5,
      "y": 0,
      "z": -6,
      "name": "Soil_Dirt"
    },
    {
      "x": -5,
      "y": 1,
      "z": -6,
      "name": "Soil_Grass"
    },
    {
      "x": -5,
      "y": 0,
      "z": -5,
      "name": "Soil_Dirt"
    },
    {
      "x": -5,
      "y": 1,
      "z": -5,
      "name": "Soil_Grass"
    },
    {
      "x": -5,
      "y": 2,
      "z": -5,
      "name": "Rock_Sandstone_White_Brick_Smooth_Half",
      "rotation": 6
    },
    {
      "x": -5,
      "y": 0,
      "z": -4,
      "name": "Soil_Dirt"
    },
    {
      "x": -5,
      "y": 1,
      "z": -4,
      "name": "Soil_Grass"
    },
    {
      "x": -5,
      "y": 2,
      "z": -4,
      "name": "Soil_Grass"
    },
    {
      "x": -5,
      "y": 3,
      "z": -4,
      "name": "Plant_Flower_Tall_Purple"
    },
    {
      "x": -5,
      "y": 0,
      "z": -3,
      "name": "Soil_Dirt"
    },
    {
      "x": -5,
      "y": 1,
      "z": -3,
      "name": "Soil_Grass"
    },
    {
      "x": -5,
      "y": 2,
      "z": -3,
      "name": "Soil_Grass"
    },
    {
      "x": -5,
      "y": 3,
      "z": -3,
      "name": "Plant_Flower_Tall_Purple"
    },
    {
      "x": -5,
      "y": 0,
      "z": -2,
      "name": "Soil_Dirt"
    },
    {
      "x": -5,
      "y": 1,
      "z": -2,
      "name": "Soil_Grass"
    },
    {
      "x": -5,
      "y": 2,
      "z": -2,
      "name": "Soil_Grass"
    },
    {
      "x": -5,
      "y": 3,
      "z": -2,
      "name": "Plant_Flower_Tall_Purple"
    },
    {
      "x": -5,
      "y": 0,
      "z": -1,
      "name": "Soil_Dirt"
    },
    {
      "x": -5,
      "y": 1,
      "z": -1,
      "name": "Rock_Sandstone_White"
    },
    {
      "x": -5,
      "y": 2,
      "z": -1,
      "name": "Rock_Sandstone_White_Brick_Smooth_Half",
      "rotation": 4
    },
    {
      "x": -5,
      "y": 0,
      "z": 0,
      "name": "Soil_Dirt"
    },
    {
      "x": -5,
      "y": 1,
      "z": 0,
      "name": "Rock_Sandstone_White"
    },
    {
      "x": -5,
      "y": 0,
      "z": 1,
      "name": "Soil_Dirt"
    },
    {
      "x": -5,
      "y": 1,
      "z": 1,
      "name": "Rock_Sandstone_White"
    },
    {
      "x": -5,
      "y": 0,
      "z": 2,
      "name": "Soil_Dirt"
    },
    {
      "x": -5,
      "y": 1,
      "z": 2,
      "name": "Rock_Sandstone_White"
    },
    {
      "x": -5,
      "y": 2,
      "z": 2,
      "name": "Rock_Sandstone_White_Brick_Smooth_Half",
      "rotation": 6
    },
    {
      "x": -5,
      "y": 0,
      "z": 3,
      "name": "Soil_Dirt"
    },
    {
      "x": -5,
      "y": 1,
      "z": 3,
      "name": "Soil_Grass"
    },
    {
      "x": -5,
      "y": 2,
      "z": 3,
      "name": "Soil_Grass"
    },
    {
      "x": -5,
      "y": 3,
      "z": 3,
      "name": "Plant_Flower_Tall_Purple"
    },
    {
      "x": -5,
      "y": 0,
      "z": 4,
      "name": "Soil_Dirt"
    },
    {
      "x": -5,
      "y": 1,
      "z": 4,
      "name": "Soil_Grass"
    },
    {
      "x": -5,
      "y": 2,
      "z": 4,
      "name": "Soil_Grass"
    },
    {
      "x": -5,
      "y": 3,
      "z": 4,
      "name": "Plant_Flower_Tall_Purple"
    },
    {
      "x": -5,
      "y": 0,
      "z": 5,
      "name": "Soil_Dirt"
    },
    {
      "x": -5,
      "y": 1,
      "z": 5,
      "name": "Soil_Grass"
    },
    {
      "x": -5,
      "y": 2,
      "z": 5,
      "name": "Soil_Grass"
    },
    {
      "x": -5,
      "y": 3,
      "z": 5,
      "name": "Plant_Flower_Tall_Purple"
    },
    {
      "x": -5,
      "y": 0,
      "z": 6,
      "name": "Soil_Dirt"
    },
    {
      "x": -5,
      "y": 1,
      "z": 6,
      "name": "Soil_Grass"
    },
    {
      "x": -5,
      "y": 2,
      "z": 6,
      "name": "Rock_Sandstone_White_Brick_Smooth_Half",
      "rotation": 4
    },
    {
      "x": -5,
      "y": 0,
      "z": 7,
      "name": "Soil_Dirt"
    },
    {
      "x": -5,
      "y": 1,
      "z": 7,
      "name": "Soil_Grass"
    },
    {
      "x": -4,
      "y": 0,
      "z": -6,
      "name": "Soil_Dirt"
    },
    {
      "x": -4,
      "y": 1,
      "z": -6,
      "name": "Soil_Grass"
    },
    {
      "x": -4,
      "y": 0,
      "z": -5,
      "name": "Soil_Dirt"
    },
    {
      "x": -4,
      "y": 1,
      "z": -5,
      "name": "Soil_Grass"
    },
    {
      "x": -4,
      "y": 2,
      "z": -5,
      "name": "Rock_Sandstone_White_Brick_Smooth_Half",
      "rotation": 6
    },
    {
      "x": -4,
      "y": 0,
      "z": -4,
      "name": "Soil_Dirt"
    },
    {
      "x": -4,
      "y": 1,
      "z": -4,
      "name": "Soil_Grass"
    },
    {
      "x": -4,
      "y": 2,
      "z": -4,
      "name": "Soil_Grass"
    },
    {
      "x": -4,
      "y": 3,
      "z": -4,
      "name": "Plant_Flower_Tall_Purple"
    },
    {
      "x": -4,
      "y": 0,
      "z": -3,
      "name": "Soil_Dirt"
    },
    {
      "x": -4,
      "y": 1,
      "z": -3,
      "name": "Soil_Grass"
    },
    {
      "x": -4,
      "y": 2,
      "z": -3,
      "name": "Soil_Grass"
    },
    {
      "x": -4,
      "y": 3,
      "z": -3,
      "name": "Rock_Sandstone_White_Brick_Smooth"
    },
    {
      "x": -4,
      "y": 4,
      "z": -3,
      "name": "Furniture_Village_Brazier"
    },
    {
      "x": -4,
      "y": 6,
      "z": -3,
      "name": "*Rock_Sandstone_White_Brick_Stairs_State_Definitions_Corner_Left",
      "rotation": 9
    },
    {
      "x": -4,
      "y": 7,
      "z": -3,
      "name": "*Rock_Sandstone_White_Brick_Stairs_State_Definitions_Corner_Left",
      "rotation": 9
    },
    {
      "x": -4,
      "y": 0,
      "z": -2,
      "name": "Soil_Dirt"
    },
    {
      "x": -4,
      "y": 1,
      "z": -2,
      "name": "Soil_Grass"
    },
    {
      "x": -4,
      "y": 2,
      "z": -2,
      "name": "Soil_Grass"
    },
    {
      "x": -4,
      "y": 3,
      "z": -2,
      "name": "Rock_Sandstone_White_Brick_Half",
      "rotation": 7
    },
    {
      "x": -4,
      "y": 4,
      "z": -2,
      "name": "Rock_Sandstone_White_Brick_Half",
      "rotation": 7
    },
    {
      "x": -4,
      "y": 5,
      "z": -2,
      "name": "Rock_Sandstone_White_Brick_Half",
      "rotation": 7
    },
    {
      "x": -4,
      "y": 6,
      "z": -2,
      "name": "Rock_Sandstone_White_Brick_Stairs",
      "rotation": 9
    },
    {
      "x": -4,
      "y": 7,
      "z": -2,
      "name": "Rock_Sandstone_White_Brick_Stairs",
      "rotation": 9
    },
    {
      "x": -4,
      "y": 0,
      "z": -1,
      "name": "Soil_Dirt"
    },
    {
      "x": -4,
      "y": 1,
      "z": -1,
      "name": "Rock_Sandstone_White"
    },
    {
      "x": -4,
      "y": 2,
      "z": -1,
      "name": "Rock_Sandstone_White_Brick_Half",
      "rotation": 4
    },
    {
      "x": -4,
      "y": 6,
      "z": -1,
      "name": "Rock_Sandstone_White_Brick_Stairs",
      "rotation": 9
    },
    {
      "x": -4,
      "y": 7,
      "z": -1,
      "name": "Rock_Sandstone_White_Brick_Stairs",
      "rotation": 9
    },
    {
      "x": -4,
      "y": 0,
      "z": 0,
      "name": "Soil_Dirt"
    },
    {
      "x": -4,
      "y": 1,
      "z": 0,
      "name": "Rock_Sandstone_White"
    },
    {
      "x": -4,
      "y": 6,
      "z": 0,
      "name": "Rock_Sandstone_White_Brick_Stairs",
      "rotation": 9
    },
    {
      "x": -4,
      "y": 7,
      "z": 0,
      "name": "Rock_Sandstone_White_Brick_Stairs",
      "rotation": 9
    },
    {
      "x": -4,
      "y": 0,
      "z": 1,
      "name": "Soil_Dirt"
    },
    {
      "x": -4,
      "y": 1,
      "z": 1,
      "name": "Rock_Sandstone_White"
    },
    {
      "x": -4,
      "y": 6,
      "z": 1,
      "name": "Rock_Sandstone_White_Brick_Stairs",
      "rotation": 9
    },
    {
      "x": -4,
      "y": 7,
      "z": 1,
      "name": "Rock_Sandstone_White_Brick_Stairs",
      "rotation": 9
    },
    {
      "x": -4,
      "y": 0,
      "z": 2,
      "name": "Soil_Dirt"
    },
    {
      "x": -4,
      "y": 1,
      "z": 2,
      "name": "Rock_Sandstone_White"
    },
    {
      "x": -4,
      "y": 2,
      "z": 2,
      "name": "Rock_Sandstone_White_Brick_Half",
      "rotation": 6
    },
    {
      "x": -4,
      "y": 6,
      "z": 2,
      "name": "Rock_Sandstone_White_Brick_Stairs",
      "rotation": 9
    },
    {
      "x": -4,
      "y": 7,
      "z": 2,
      "name": "Rock_Sandstone_White_Brick_Stairs",
      "rotation": 9
    },
    {
      "x": -4,
      "y": 0,
      "z": 3,
      "name": "Soil_Dirt"
    },
    {
      "x": -4,
      "y": 1,
      "z": 3,
      "name": "Soil_Grass"
    },
    {
      "x": -4,
      "y": 2,
      "z": 3,
      "name": "Soil_Grass"
    },
    {
      "x": -4,
      "y": 3,
      "z": 3,
      "name": "Rock_Sandstone_White_Brick_Half",
      "rotation": 7
    },
    {
      "x": -4,
      "y": 4,
      "z": 3,
      "name": "Rock_Sandstone_White_Brick_Half",
      "rotation": 7
    },
    {
      "x": -4,
      "y": 5,
      "z": 3,
      "name": "Rock_Sandstone_White_Brick_Half",
      "rotation": 7
    },
    {
      "x": -4,
      "y": 6,
      "z": 3,
      "name": "Rock_Sandstone_White_Brick_Stairs",
      "rotation": 9
    },
    {
      "x": -4,
      "y": 7,
      "z": 3,
      "name": "Rock_Sandstone_White_Brick_Stairs",
      "rotation": 9
    },
    {
      "x": -4,
      "y": 0,
      "z": 4,
      "name": "Soil_Dirt"
    },
    {
      "x": -4,
      "y": 1,
      "z": 4,
      "name": "Soil_Grass"
    },
    {
      "x": -4,
      "y": 2,
      "z": 4,
      "name": "Soil_Grass"
    },
    {
      "x": -4,
      "y": 3,
      "z": 4,
      "name": "Rock_Sandstone_White_Brick_Smooth"
    },
    {
      "x": -4,
      "y": 4,
      "z": 4,
      "name": "Furniture_Village_Brazier"
    },
    {
      "x": -4,
      "y": 6,
      "z": 4,
      "name": "*Rock_Sandstone_White_Brick_Stairs_State_Definitions_Corner_Left",
      "rotation": 10
    },
    {
      "x": -4,
      "y": 7,
      "z": 4,
      "name": "*Rock_Sandstone_White_Brick_Stairs_State_Definitions_Corner_Left",
      "rotation": 10
    },
    {
      "x": -4,
      "y": 0,
      "z": 5,
      "name": "Soil_Dirt"
    },
    {
      "x": -4,
      "y": 1,
      "z": 5,
      "name": "Soil_Grass"
    },
    {
      "x": -4,
      "y": 2,
      "z": 5,
      "name": "Soil_Grass"
    },
    {
      "x": -4,
      "y": 3,
      "z": 5,
      "name": "Plant_Flower_Tall_Purple"
    },
    {
      "x": -4,
      "y": 0,
      "z": 6,
      "name": "Soil_Dirt"
    },
    {
      "x": -4,
      "y": 1,
      "z": 6,
      "name": "Soil_Grass"
    },
    {
      "x": -4,
      "y": 2,
      "z": 6,
      "name": "Rock_Sandstone_White_Brick_Smooth_Half",
      "rotation": 4
    },
    {
      "x": -4,
      "y": 0,
      "z": 7,
      "name": "Soil_Dirt"
    },
    {
      "x": -4,
      "y": 1,
      "z": 7,
      "name": "Soil_Grass"
    },
    {
      "x": -3,
      "y": 0,
      "z": -6,
      "name": "Soil_Dirt"
    },
    {
      "x": -3,
      "y": 1,
      "z": -6,
      "name": "Soil_Grass"
    },
    {
      "x": -3,
      "y": 0,
      "z": -5,
      "name": "Soil_Dirt"
    },
    {
      "x": -3,
      "y": 1,
      "z": -5,
      "name": "Soil_Grass"
    },
    {
      "x": -3,
      "y": 2,
      "z": -5,
      "name": "Rock_Sandstone_White_Brick_Smooth_Half",
      "rotation": 6
    },
    {
      "x": -3,
      "y": 0,
      "z": -4,
      "name": "Soil_Dirt"
    },
    {
      "x": -3,
      "y": 1,
      "z": -4,
      "name": "Soil_Grass"
    },
    {
      "x": -3,
      "y": 2,
      "z": -4,
      "name": "Soil_Grass"
    },
    {
      "x": -3,
      "y": 3,
      "z": -4,
      "name": "Plant_Flower_Tall_Purple"
    },
    {
      "x": -3,
      "y": 0,
      "z": -3,
      "name": "Soil_Dirt"
    },
    {
      "x": -3,
      "y": 1,
      "z": -3,
      "name": "Soil_Grass"
    },
    {
      "x": -3,
      "y": 2,
      "z": -3,
      "name": "Soil_Grass"
    },
    {
      "x": -3,
      "y": 3,
      "z": -3,
      "name": "Rock_Sandstone_White_Brick_Half",
      "rotation": 6
    },
    {
      "x": -3,
      "y": 4,
      "z": -3,
      "name": "Rock_Sandstone_White_Brick_Half",
      "rotation": 6
    },
    {
      "x": -3,
      "y": 5,
      "z": -3,
      "name": "Rock_Sandstone_White_Brick_Half",
      "rotation": 6
    },
    {
      "x": -3,
      "y": 6,
      "z": -3,
      "name": "Rock_Sandstone_White_Brick_Stairs",
      "rotation": 8
    },
    {
      "x": -3,
      "y": 7,
      "z": -3,
      "name": "Rock_Sandstone_White_Brick_Stairs",
      "rotation": 8
    },
    {
      "x": -3,
      "y": 0,
      "z": -2,
      "name": "Rock_Sandstone_White_Brick_Smooth"
    },
    {
      "x": -3,
      "y": 1,
      "z": -2,
      "name": "Soil_Grass"
    },
    {
      "x": -3,
      "y": 2,
      "z": -2,
      "name": "Rock_Sandstone_White_Brick_Smooth"
    },
    {
      "x": -3,
      "y": 3,
      "z": -2,
      "name": "Rock_Sandstone_White_Brick_Ornate"
    },
    {
      "x": -3,
      "y": 4,
      "z": -2,
      "name": "Rock_Sandstone_White_Brick"
    },
    {
      "x": -3,
      "y": 5,
      "z": -2,
      "name": "Rock_Sandstone_White_Brick"
    },
    {
      "x": -3,
      "y": 6,
      "z": -2,
      "name": "Rock_Sandstone_White_Brick"
    },
    {
      "x": -3,
      "y": 7,
      "z": -2,
      "name": "Rock_Sandstone_White_Brick_Decorative"
    },
    {
      "x": -3,
      "y": 8,
      "z": -2,
      "name": "Rock_Sandstone_White_Brick_Smooth_Half"
    },
    {
      "x": -3,
      "y": 0,
      "z": -1,
      "name": "Rock_Sandstone_White_Brick_Smooth"
    },
    {
      "x": -3,
      "y": 1,
      "z": -1,
      "name": "*Rock_Sandstone_White_Brick_Stairs_State_Definitions_Inverted_Corner_Left"
    },
    {
      "x": -3,
      "y": 2,
      "z": -1,
      "name": "Rock_Sandstone_White_Brick_Half",
      "rotation": 4
    },
    {
      "x": -3,
      "y": 3,
      "z": -1,
      "name": "Rock_Sandstone_White_Brick_Half",
      "rotation": 4
    },
    {
      "x": -3,
      "y": 4,
      "z": -1,
      "name": "Rock_Sandstone_White_Brick_Half",
      "rotation": 4
    },
    {
      "x": -3,
      "y": 5,
      "z": -1,
      "name": "Rock_Sandstone_White_Brick_Stairs",
      "rotation": 10
    },
    {
      "x": -3,
      "y": 6,
      "z": -1,
      "name": "Rock_Sandstone_White_Brick_Decorative"
    },
    {
      "x": -3,
      "y": 7,
      "z": -1,
      "name": "Rock_Sandstone_White_Brick_Decorative"
    },
    {
      "x": -3,
      "y": 8,
      "z": -1,
      "name": "Rock_Sandstone_White_Brick_Smooth_Half"
    },
    {
      "x": -3,
      "y": 0,
      "z": 0,
      "name": "Rock_Sandstone_White_Brick_Smooth"
    },
    {
      "x": -3,
      "y": 1,
      "z": 0,
      "name": "Rock_Sandstone_White_Brick_Stairs",
      "rotation": 1
    },
    {
      "x": -3,
      "y": 6,
      "z": 0,
      "name": "Rock_Sandstone_White_Brick_Decorative"
    },
    {
      "x": -3,
      "y": 7,
      "z": 0,
      "name": "Rock_Sandstone_White_Brick_Decorative"
    },
    {
      "x": -3,
      "y": 8,
      "z": 0,
      "name": "Rock_Sandstone_White_Brick_Smooth_Half"
    },
    {
      "x": -3,
      "y": 0,
      "z": 1,
      "name": "Rock_Sandstone_White_Brick_Smooth"
    },
    {
      "x": -3,
      "y": 1,
      "z": 1,
      "name": "Rock_Sandstone_White_Brick_Stairs",
      "rotation": 1
    },
    {
      "x": -3,
      "y": 6,
      "z": 1,
      "name": "Rock_Sandstone_White_Brick_Decorative"
    },
    {
      "x": -3,
      "y": 7,
      "z": 1,
      "name": "Rock_Sandstone_White_Brick_Decorative"
    },
    {
      "x": -3,
      "y": 8,
      "z": 1,
      "name": "Rock_Sandstone_White_Brick_Smooth_Half"
    },
    {
      "x": -3,
      "y": 0,
      "z": 2,
      "name": "Rock_Sandstone_White_Brick_Smooth"
    },
    {
      "x": -3,
      "y": 1,
      "z": 2,
      "name": "*Rock_Sandstone_White_Brick_Stairs_State_Definitions_Inverted_Corner_Right",
      "rotation": 2
    },
    {
      "x": -3,
      "y": 2,
      "z": 2,
      "name": "Rock_Sandstone_White_Brick_Half",
      "rotation": 6
    },
    {
      "x": -3,
      "y": 3,
      "z": 2,
      "name": "Rock_Sandstone_White_Brick_Half",
      "rotation": 6
    },
    {
      "x": -3,
      "y": 4,
      "z": 2,
      "name": "Rock_Sandstone_White_Brick_Half",
      "rotation": 6
    },
    {
      "x": -3,
      "y": 5,
      "z": 2,
      "name": "Rock_Sandstone_White_Brick_Stairs",
      "rotation": 8
    },
    {
      "x": -3,
      "y": 6,
      "z": 2,
      "name": "Rock_Sandstone_White_Brick_Decorative"
    },
    {
      "x": -3,
      "y": 7,
      "z": 2,
      "name": "Rock_Sandstone_White_Brick_Decorative"
    },
    {
      "x": -3,
      "y": 8,
      "z": 2,
      "name": "Rock_Sandstone_White_Brick_Smooth_Half"
    },
    {
      "x": -3,
      "y": 0,
      "z": 3,
      "name": "Rock_Sandstone_White_Brick_Smooth"
    },
    {
      "x": -3,
      "y": 1,
      "z": 3,
      "name": "Soil_Grass"
    },
    {
      "x": -3,
      "y": 2,
      "z": 3,
      "name": "Rock_Sandstone_White_Brick_Smooth"
    },
    {
      "x": -3,
      "y": 3,
      "z": 3,
      "name": "Rock_Sandstone_White_Brick_Ornate"
    },
    {
      "x": -3,
      "y": 4,
      "z": 3,
      "name": "Rock_Sandstone_White_Brick"
    },
    {
      "x": -3,
      "y": 5,
      "z": 3,
      "name": "Rock_Sandstone_White_Brick"
    },
    {
      "x": -3,
      "y": 6,
      "z": 3,
      "name": "Rock_Sandstone_White_Brick"
    },
    {
      "x": -3,
      "y": 7,
      "z": 3,
      "name": "Rock_Sandstone_White_Brick_Decorative"
    },
    {
      "x": -3,
      "y": 8,
      "z": 3,
      "name": "Rock_Sandstone_White_Brick_Smooth_Half"
    },
    {
      "x": -3,
      "y": 0,
      "z": 4,
      "name": "Soil_Dirt"
    },
    {
      "x": -3,
      "y": 1,
      "z": 4,
      "name": "Soil_Grass"
    },
    {
      "x": -3,
      "y": 2,
      "z": 4,
      "name": "Soil_Grass"
    },
    {
      "x": -3,
      "y": 3,
      "z": 4,
      "name": "Rock_Sandstone_White_Brick_Half",
      "rotation": 4
    },
    {
      "x": -3,
      "y": 4,
      "z": 4,
      "name": "Rock_Sandstone_White_Brick_Half",
      "rotation": 4
    },
    {
      "x": -3,
      "y": 5,
      "z": 4,
      "name": "Rock_Sandstone_White_Brick_Half",
      "rotation": 4
    },
    {
      "x": -3,
      "y": 6,
      "z": 4,
      "name": "Rock_Sandstone_White_Brick_Stairs",
      "rotation": 10
    },
    {
      "x": -3,
      "y": 7,
      "z": 4,
      "name": "Rock_Sandstone_White_Brick_Stairs",
      "rotation": 10
    },
    {
      "x": -3,
      "y": 0,
      "z": 5,
      "name": "Soil_Dirt"
    },
    {
      "x": -3,
      "y": 1,
      "z": 5,
      "name": "Soil_Grass"
    },
    {
      "x": -3,
      "y": 2,
      "z": 5,
      "name": "Soil_Grass"
    },
    {
      "x": -3,
      "y": 3,
      "z": 5,
      "name": "Plant_Flower_Tall_Purple"
    },
    {
      "x": -3,
      "y": 0,
      "z": 6,
      "name": "Soil_Dirt"
    },
    {
      "x": -3,
      "y": 1,
      "z": 6,
      "name": "Soil_Grass"
    },
    {
      "x": -3,
      "y": 2,
      "z": 6,
      "name": "Rock_Sandstone_White_Brick_Smooth_Half",
      "rotation": 4
    },
    {
      "x": -3,
      "y": 0,
      "z": 7,
      "name": "Soil_Dirt"
    },
    {
      "x": -3,
      "y": 1,
      "z": 7,
      "name": "Soil_Grass"
    },
    {
      "x": -2,
      "y": 0,
      "z": -6,
      "name": "Soil_Dirt"
    },
    {
      "x": -2,
      "y": 1,
      "z": -6,
      "name": "Soil_Grass"
    },
    {
      "x": -2,
      "y": 0,
      "z": -5,
      "name": "Soil_Dirt"
    },
    {
      "x": -2,
      "y": 1,
      "z": -5,
      "name": "Rock_Sandstone_White_Brick_Smooth"
    },
    {
      "x": -2,
      "y": 0,
      "z": -4,
      "name": "Soil_Dirt"
    },
    {
      "x": -2,
      "y": 1,
      "z": -4,
      "name": "Rock_Sandstone_White"
    },
    {
      "x": -2,
      "y": 2,
      "z": -4,
      "name": "Rock_Sandstone_White_Brick_Smooth_Half",
      "rotation": 5
    },
    {
      "x": -2,
      "y": 0,
      "z": -3,
      "name": "Soil_Dirt"
    },
    {
      "x": -2,
      "y": 1,
      "z": -3,
      "name": "Rock_Sandstone_White"
    },
    {
      "x": -2,
      "y": 2,
      "z": -3,
      "name": "Rock_Sandstone_White_Brick_Half",
      "rotation": 5
    },
    {
      "x": -2,
      "y": 6,
      "z": -3,
      "name": "Rock_Sandstone_White_Brick_Stairs",
      "rotation": 8
    },
    {
      "x": -2,
      "y": 7,
      "z": -3,
      "name": "Rock_Sandstone_White_Brick_Stairs",
      "rotation": 8
    },
    {
      "x": -2,
      "y": 0,
      "z": -2,
      "name": "Rock_Sandstone_White_Brick_Smooth"
    },
    {
      "x": -2,
      "y": 1,
      "z": -2,
      "name": "*Rock_Sandstone_White_Brick_Stairs_State_Definitions_Inverted_Corner_Right",
      "rotation": 1
    },
    {
      "x": -2,
      "y": 2,
      "z": -2,
      "name": "Rock_Sandstone_White_Brick_Half",
      "rotation": 5
    },
    {
      "x": -2,
      "y": 3,
      "z": -2,
      "name": "Rock_Sandstone_White_Brick_Half",
      "rotation": 5
    },
    {
      "x": -2,
      "y": 4,
      "z": -2,
      "name": "Rock_Sandstone_White_Brick_Half",
      "rotation": 5
    },
    {
      "x": -2,
      "y": 5,
      "z": -2,
      "name": "Rock_Sandstone_White_Brick_Stairs",
      "rotation": 11
    },
    {
      "x": -2,
      "y": 6,
      "z": -2,
      "name": "Rock_Sandstone_White_Brick_Decorative"
    },
    {
      "x": -2,
      "y": 7,
      "z": -2,
      "name": "Rock_Sandstone_White_Brick_Decorative"
    },
    {
      "x": -2,
      "y": 8,
      "z": -2,
      "name": "Rock_Sandstone_White_Brick_Smooth_Half"
    },
    {
      "x": -2,
      "y": 0,
      "z": -1,
      "name": "Rock_Sandstone_White_Brick_Smooth"
    },
    {
      "x": -2,
      "y": 6,
      "z": -1,
      "name": "*Rock_Sandstone_White_Brick_Stairs_State_Definitions_Inverted_Corner_Left",
      "rotation": 11
    },
    {
      "x": -2,
      "y": 7,
      "z": -1,
      "name": "Rock_Sandstone_White_Brick_Decorative"
    },
    {
      "x": -2,
      "y": 0,
      "z": 0,
      "name": "Rock_Sandstone_White_Brick_Smooth"
    },
    {
      "x": -2,
      "y": 6,
      "z": 0,
      "name": "Rock_Sandstone_White_Brick_Stairs",
      "rotation": 11
    },
    {
      "x": -2,
      "y": 7,
      "z": 0,
      "name": "Rock_Sandstone_White_Brick_Decorative"
    },
    {
      "x": -2,
      "y": 0,
      "z": 1,
      "name": "Rock_Sandstone_White_Brick_Smooth"
    },
    {
      "x": -2,
      "y": 6,
      "z": 1,
      "name": "Rock_Sandstone_White_Brick_Stairs",
      "rotation": 11
    },
    {
      "x": -2,
      "y": 7,
      "z": 1,
      "name": "Rock_Sandstone_White_Brick_Decorative"
    },
    {
      "x": -2,
      "y": 0,
      "z": 2,
      "name": "Rock_Sandstone_White_Brick_Smooth"
    },
    {
      "x": -2,
      "y": 6,
      "z": 2,
      "name": "*Rock_Sandstone_White_Brick_Stairs_State_Definitions_Inverted_Corner_Right",
      "rotation": 11
    },
    {
      "x": -2,
      "y": 7,
      "z": 2,
      "name": "Rock_Sandstone_White_Brick_Decorative"
    },
    {
      "x": -2,
      "y": 0,
      "z": 3,
      "name": "Rock_Sandstone_White_Brick_Smooth"
    },
    {
      "x": -2,
      "y": 1,
      "z": 3,
      "name": "*Rock_Sandstone_White_Brick_Stairs_State_Definitions_Inverted_Corner_Left",
      "rotation": 1
    },
    {
      "x": -2,
      "y": 2,
      "z": 3,
      "name": "Rock_Sandstone_White_Brick_Half",
      "rotation": 5
    },
    {
      "x": -2,
      "y": 3,
      "z": 3,
      "name": "Rock_Sandstone_White_Brick_Half",
      "rotation": 5
    },
    {
      "x": -2,
      "y": 4,
      "z": 3,
      "name": "Rock_Sandstone_White_Brick_Half",
      "rotation": 5
    },
    {
      "x": -2,
      "y": 5,
      "z": 3,
      "name": "Rock_Sandstone_White_Brick_Stairs",
      "rotation": 11
    },
    {
      "x": -2,
      "y": 6,
      "z": 3,
      "name": "Rock_Sandstone_White_Brick_Decorative"
    },
    {
      "x": -2,
      "y": 7,
      "z": 3,
      "name": "Rock_Sandstone_White_Brick_Decorative"
    },
    {
      "x": -2,
      "y": 8,
      "z": 3,
      "name": "Rock_Sandstone_White_Brick_Smooth_Half"
    },
    {
      "x": -2,
      "y": 0,
      "z": 4,
      "name": "Soil_Dirt"
    },
    {
      "x": -2,
      "y": 1,
      "z": 4,
      "name": "Rock_Sandstone_White"
    },
    {
      "x": -2,
      "y": 2,
      "z": 4,
      "name": "Rock_Sandstone_White_Brick_Half",
      "rotation": 5
    },
    {
      "x": -2,
      "y": 6,
      "z": 4,
      "name": "Rock_Sandstone_White_Brick_Stairs",
      "rotation": 10
    },
    {
      "x": -2,
      "y": 7,
      "z": 4,
      "name": "Rock_Sandstone_White_Brick_Stairs",
      "rotation": 10
    },
    {
      "x": -2,
      "y": 0,
      "z": 5,
      "name": "Soil_Dirt"
    },
    {
      "x": -2,
      "y": 1,
      "z": 5,
      "name": "Rock_Sandstone_White"
    },
    {
      "x": -2,
      "y": 2,
      "z": 5,
      "name": "Rock_Sandstone_White_Brick_Smooth_Half",
      "rotation": 5
    },
    {
      "x": -2,
      "y": 0,
      "z": 6,
      "name": "Soil_Dirt"
    },
    {
      "x": -2,
      "y": 1,
      "z": 6,
      "name": "Rock_Sandstone_White_Brick_Smooth"
    },
    {
      "x": -2,
      "y": 0,
      "z": 7,
      "name": "Soil_Dirt"
    },
    {
      "x": -2,
      "y": 1,
      "z": 7,
      "name": "Soil_Grass"
    },
    {
      "x": -1,
      "y": 0,
      "z": -6,
      "name": "Soil_Dirt"
    },
    {
      "x": -1,
      "y": 1,
      "z": -6,
      "name": "Soil_Grass"
    },
    {
      "x": -1,
      "y": 0,
      "z": -5,
      "name": "Soil_Dirt"
    },
    {
      "x": -1,
      "y": 1,
      "z": -5,
      "name": "Rock_Sandstone_White_Brick_Smooth"
    },
    {
      "x": -1,
      "y": 0,
      "z": -4,
      "name": "Soil_Dirt"
    },
    {
      "x": -1,
      "y": 1,
      "z": -4,
      "name": "Rock_Sandstone_White"
    },
    {
      "x": -1,
      "y": 0,
      "z": -3,
      "name": "Soil_Dirt"
    },
    {
      "x": -1,
      "y": 1,
      "z": -3,
      "name": "Rock_Sandstone_White"
    },
    {
      "x": -1,
      "y": 6,
      "z": -3,
      "name": "Rock_Sandstone_White_Brick_Stairs",
      "rotation": 8
    },
    {
      "x": -1,
      "y": 7,
      "z": -3,
      "name": "Rock_Sandstone_White_Brick_Stairs",
      "rotation": 8
    },
    {
      "x": -1,
      "y": 0,
      "z": -2,
      "name": "Rock_Sandstone_White_Brick_Smooth"
    },
    {
      "x": -1,
      "y": 1,
      "z": -2,
      "name": "Rock_Sandstone_White_Brick_Stairs"
    },
    {
      "x": -1,
      "y": 6,
      "z": -2,
      "name": "Rock_Sandstone_White_Brick_Decorative"
    },
    {
      "x": -1,
      "y": 7,
      "z": -2,
      "name": "Rock_Sandstone_White_Brick_Decorative"
    },
    {
      "x": -1,
      "y": 8,
      "z": -2,
      "name": "Rock_Sandstone_White_Brick_Smooth_Half"
    },
    {
      "x": -1,
      "y": 0,
      "z": -1,
      "name": "Rock_Sandstone_White_Brick_Smooth"
    },
    {
      "x": -1,
      "y": 6,
      "z": -1,
      "name": "Rock_Sandstone_White_Brick_Stairs",
      "rotation": 10
    },
    {
      "x": -1,
      "y": 7,
      "z": -1,
      "name": "Rock_Sandstone_White_Brick_Decorative"
    },
    {
      "x": -1,
      "y": 0,
      "z": 0,
      "name": "Rock_Sandstone_White_Brick_Smooth"
    },
    {
      "x": -1,
      "y": 6,
      "z": 0,
      "name": "Rock_Sandstone_White_Brick_Half",
      "rotation": 8
    },
    {
      "x": -1,
      "y": 7,
      "z": 0,
      "name": "Rock_Sandstone_White_Brick_Decorative"
    },
    {
      "x": -1,
      "y": 0,
      "z": 1,
      "name": "Rock_Sandstone_White_Brick_Smooth"
    },
    {
      "x": -1,
      "y": 6,
      "z": 1,
      "name": "Rock_Sandstone_White_Brick_Half",
      "rotation": 8
    },
    {
      "x": -1,
      "y": 7,
      "z": 1,
      "name": "Rock_Sandstone_White_Brick_Decorative"
    },
    {
      "x": -1,
      "y": 0,
      "z": 2,
      "name": "Rock_Sandstone_White_Brick_Smooth"
    },
    {
      "x": -1,
      "y": 6,
      "z": 2,
      "name": "Rock_Sandstone_White_Brick_Stairs",
      "rotation": 8
    },
    {
      "x": -1,
      "y": 7,
      "z": 2,
      "name": "Rock_Sandstone_White_Brick_Decorative"
    },
    {
      "x": -1,
      "y": 0,
      "z": 3,
      "name": "Rock_Sandstone_White_Brick_Smooth"
    },
    {
      "x": -1,
      "y": 1,
      "z": 3,
      "name": "Rock_Sandstone_White_Brick_Stairs",
      "rotation": 2
    },
    {
      "x": -1,
      "y": 6,
      "z": 3,
      "name": "Rock_Sandstone_White_Brick_Decorative"
    },
    {
      "x": -1,
      "y": 7,
      "z": 3,
      "name": "Rock_Sandstone_White_Brick_Decorative"
    },
    {
      "x": -1,
      "y": 8,
      "z": 3,
      "name": "Rock_Sandstone_White_Brick_Smooth_Half"
    },
    {
      "x": -1,
      "y": 0,
      "z": 4,
      "name": "Soil_Dirt"
    },
    {
      "x": -1,
      "y": 1,
      "z": 4,
      "name": "Rock_Sandstone_White"
    },
    {
      "x": -1,
      "y": 6,
      "z": 4,
      "name": "Rock_Sandstone_White_Brick_Stairs",
      "rotation": 10
    },
    {
      "x": -1,
      "y": 7,
      "z": 4,
      "name": "Rock_Sandstone_White_Brick_Stairs",
      "rotation": 10
    },
    {
      "x": -1,
      "y": 0,
      "z": 5,
      "name": "Soil_Dirt"
    },
    {
      "x": -1,
      "y": 1,
      "z": 5,
      "name": "Rock_Sandstone_White"
    },
    {
      "x": -1,
      "y": 0,
      "z": 6,
      "name": "Soil_Dirt"
    },
    {
      "x": -1,
      "y": 1,
      "z": 6,
      "name": "Rock_Sandstone_White_Brick_Smooth"
    },
    {
      "x": -1,
      "y": 0,
      "z": 7,
      "name": "Soil_Dirt"
    },
    {
      "x": -1,
      "y": 1,
      "z": 7,
      "name": "Soil_Grass"
    },
    {
      "x": 0,
      "y": 0,
      "z": -6,
      "name": "Soil_Dirt"
    },
    {
      "x": 0,
      "y": 1,
      "z": -6,
      "name": "Soil_Grass"
    },
    {
      "x": 0,
      "y": 0,
      "z": -5,
      "name": "Soil_Dirt"
    },
    {
      "x": 0,
      "y": 1,
      "z": -5,
      "name": "Rock_Sandstone_White_Brick_Smooth"
    },
    {
      "x": 0,
      "y": 0,
      "z": -4,
      "name": "Soil_Dirt"
    },
    {
      "x": 0,
      "y": 1,
      "z": -4,
      "name": "Rock_Sandstone_White"
    },
    {
      "x": 0,
      "y": 0,
      "z": -3,
      "name": "Soil_Dirt"
    },
    {
      "x": 0,
      "y": 1,
      "z": -3,
      "name": "Rock_Sandstone_White"
    },
    {
      "x": 0,
      "y": 6,
      "z": -3,
      "name": "Rock_Sandstone_White_Brick_Stairs",
      "rotation": 8
    },
    {
      "x": 0,
      "y": 7,
      "z": -3,
      "name": "Rock_Sandstone_White_Brick_Stairs",
      "rotation": 8
    },
    {
      "x": 0,
      "y": 0,
      "z": -2,
      "name": "Rock_Sandstone_White_Brick_Smooth"
    },
    {
      "x": 0,
      "y": 1,
      "z": -2,
      "name": "Rock_Sandstone_White_Brick_Stairs"
    },
    {
      "x": 0,
      "y": 6,
      "z": -2,
      "name": "Rock_Sandstone_White_Brick_Decorative"
    },
    {
      "x": 0,
      "y": 7,
      "z": -2,
      "name": "Rock_Sandstone_White_Brick_Decorative"
    },
    {
      "x": 0,
      "y": 8,
      "z": -2,
      "name": "Rock_Sandstone_White_Brick_Smooth_Half"
    },
    {
      "x": 0,
      "y": 0,
      "z": -1,
      "name": "Rock_Sandstone_White_Brick_Smooth"
    },
    {
      "x": 0,
      "y": 6,
      "z": -1,
      "name": "Rock_Sandstone_White_Brick_Stairs",
      "rotation": 10
    },
    {
      "x": 0,
      "y": 7,
      "z": -1,
      "name": "Rock_Sandstone_White_Brick_Decorative"
    },
    {
      "x": 0,
      "y": 0,
      "z": 0,
      "name": "Rock_Sandstone_White_Brick_Smooth"
    },
    {
      "x": 0,
      "y": 6,
      "z": 0,
      "name": "Rock_Sandstone_White_Brick_Half",
      "rotation": 8
    },
    {
      "x": 0,
      "y": 7,
      "z": 0,
      "name": "Rock_Sandstone_White_Brick_Decorative"
    },
    {
      "x": 0,
      "y": 0,
      "z": 1,
      "name": "Rock_Sandstone_White_Brick_Smooth"
    },
    {
      "x": 0,
      "y": 6,
      "z": 1,
      "name": "Rock_Sandstone_White_Brick_Half",
      "rotation": 8
    },
    {
      "x": 0,
      "y": 7,
      "z": 1,
      "name": "Rock_Sandstone_White_Brick_Decorative"
    },
    {
      "x": 0,
      "y": 0,
      "z": 2,
      "name": "Rock_Sandstone_White_Brick_Smooth"
    },
    {
      "x": 0,
      "y": 6,
      "z": 2,
      "name": "Rock_Sandstone_White_Brick_Stairs",
      "rotation": 8
    },
    {
      "x": 0,
      "y": 7,
      "z": 2,
      "name": "Rock_Sandstone_White_Brick_Decorative"
    },
    {
      "x": 0,
      "y": 0,
      "z": 3,
      "name": "Rock_Sandstone_White_Brick_Smooth"
    },
    {
      "x": 0,
      "y": 1,
      "z": 3,
      "name": "Rock_Sandstone_White_Brick_Stairs",
      "rotation": 2
    },
    {
      "x": 0,
      "y": 6,
      "z": 3,
      "name": "Rock_Sandstone_White_Brick_Decorative"
    },
    {
      "x": 0,
      "y": 7,
      "z": 3,
      "name": "Rock_Sandstone_White_Brick_Decorative"
    },
    {
      "x": 0,
      "y": 8,
      "z": 3,
      "name": "Rock_Sandstone_White_Brick_Smooth_Half"
    },
    {
      "x": 0,
      "y": 0,
      "z": 4,
      "name": "Soil_Dirt"
    },
    {
      "x": 0,
      "y": 1,
      "z": 4,
      "name": "Rock_Sandstone_White"
    },
    {
      "x": 0,
      "y": 6,
      "z": 4,
      "name": "Rock_Sandstone_White_Brick_Stairs",
      "rotation": 10
    },
    {
      "x": 0,
      "y": 7,
      "z": 4,
      "name": "Rock_Sandstone_White_Brick_Stairs",
      "rotation": 10
    },
    {
      "x": 0,
      "y": 0,
      "z": 5,
      "name": "Soil_Dirt"
    },
    {
      "x": 0,
      "y": 1,
      "z": 5,
      "name": "Rock_Sandstone_White"
    },
    {
      "x": 0,
      "y": 0,
      "z": 6,
      "name": "Soil_Dirt"
    },
    {
      "x": 0,
      "y": 1,
      "z": 6,
      "name": "Rock_Sandstone_White_Brick_Smooth"
    },
    {
      "x": 0,
      "y": 0,
      "z": 7,
      "name": "Soil_Dirt"
    },
    {
      "x": 0,
      "y": 1,
      "z": 7,
      "name": "Soil_Grass"
    },
    {
      "x": 1,
      "y": 0,
      "z": -6,
      "name": "Soil_Dirt"
    },
    {
      "x": 1,
      "y": 1,
      "z": -6,
      "name": "Soil_Grass"
    },
    {
      "x": 1,
      "y": 0,
      "z": -5,
      "name": "Soil_Dirt"
    },
    {
      "x": 1,
      "y": 1,
      "z": -5,
      "name": "Rock_Sandstone_White_Brick_Smooth"
    },
    {
      "x": 1,
      "y": 0,
      "z": -4,
      "name": "Soil_Dirt"
    },
    {
      "x": 1,
      "y": 1,
      "z": -4,
      "name": "Rock_Sandstone_White"
    },
    {
      "x": 1,
      "y": 2,
      "z": -4,
      "name": "Rock_Sandstone_White_Brick_Smooth_Half",
      "rotation": 7
    },
    {
      "x": 1,
      "y": 0,
      "z": -3,
      "name": "Soil_Dirt"
    },
    {
      "x": 1,
      "y": 1,
      "z": -3,
      "name": "Rock_Sandstone_White"
    },
    {
      "x": 1,
      "y": 2,
      "z": -3,
      "name": "Rock_Sandstone_White_Brick_Half",
      "rotation": 7
    },
    {
      "x": 1,
      "y": 6,
      "z": -3,
      "name": "Rock_Sandstone_White_Brick_Stairs",
      "rotation": 8
    },
    {
      "x": 1,
      "y": 7,
      "z": -3,
      "name": "Rock_Sandstone_White_Brick_Stairs",
      "rotation": 8
    },
    {
      "x": 1,
      "y": 0,
      "z": -2,
      "name": "Rock_Sandstone_White_Brick_Smooth"
    },
    {
      "x": 1,
      "y": 1,
      "z": -2,
      "name": "*Rock_Sandstone_White_Brick_Stairs_State_Definitions_Inverted_Corner_Left",
      "rotation": 3
    },
    {
      "x": 1,
      "y": 2,
      "z": -2,
      "name": "Rock_Sandstone_White_Brick_Half",
      "rotation": 7
    },
    {
      "x": 1,
      "y": 3,
      "z": -2,
      "name": "Rock_Sandstone_White_Brick_Half",
      "rotation": 7
    },
    {
      "x": 1,
      "y": 4,
      "z": -2,
      "name": "Rock_Sandstone_White_Brick_Half",
      "rotation": 7
    },
    {
      "x": 1,
      "y": 5,
      "z": -2,
      "name": "Rock_Sandstone_White_Brick_Stairs",
      "rotation": 9
    },
    {
      "x": 1,
      "y": 6,
      "z": -2,
      "name": "Rock_Sandstone_White_Brick_Decorative"
    },
    {
      "x": 1,
      "y": 7,
      "z": -2,
      "name": "Rock_Sandstone_White_Brick_Decorative"
    },
    {
      "x": 1,
      "y": 8,
      "z": -2,
      "name": "Rock_Sandstone_White_Brick_Smooth_Half"
    },
    {
      "x": 1,
      "y": 0,
      "z": -1,
      "name": "Rock_Sandstone_White_Brick_Smooth"
    },
    {
      "x": 1,
      "y": 6,
      "z": -1,
      "name": "*Rock_Sandstone_White_Brick_Stairs_State_Definitions_Inverted_Corner_Right",
      "rotation": 9
    },
    {
      "x": 1,
      "y": 7,
      "z": -1,
      "name": "Rock_Sandstone_White_Brick_Decorative"
    },
    {
      "x": 1,
      "y": 0,
      "z": 0,
      "name": "Rock_Sandstone_White_Brick_Smooth"
    },
    {
      "x": 1,
      "y": 6,
      "z": 0,
      "name": "Rock_Sandstone_White_Brick_Stairs",
      "rotation": 9
    },
    {
      "x": 1,
      "y": 7,
      "z": 0,
      "name": "Rock_Sandstone_White_Brick_Decorative"
    },
    {
      "x": 1,
      "y": 0,
      "z": 1,
      "name": "Rock_Sandstone_White_Brick_Smooth"
    },
    {
      "x": 1,
      "y": 6,
      "z": 1,
      "name": "Rock_Sandstone_White_Brick_Stairs",
      "rotation": 9
    },
    {
      "x": 1,
      "y": 7,
      "z": 1,
      "name": "Rock_Sandstone_White_Brick_Decorative"
    },
    {
      "x": 1,
      "y": 0,
      "z": 2,
      "name": "Rock_Sandstone_White_Brick_Smooth"
    },
    {
      "x": 1,
      "y": 6,
      "z": 2,
      "name": "*Rock_Sandstone_White_Brick_Stairs_State_Definitions_Inverted_Corner_Left",
      "rotation": 9
    },
    {
      "x": 1,
      "y": 7,
      "z": 2,
      "name": "Rock_Sandstone_White_Brick_Decorative"
    },
    {
      "x": 1,
      "y": 0,
      "z": 3,
      "name": "Rock_Sandstone_White_Brick_Smooth"
    },
    {
      "x": 1,
      "y": 1,
      "z": 3,
      "name": "*Rock_Sandstone_White_Brick_Stairs_State_Definitions_Inverted_Corner_Right",
      "rotation": 3
    },
    {
      "x": 1,
      "y": 2,
      "z": 3,
      "name": "Rock_Sandstone_White_Brick_Half",
      "rotation": 7
    },
    {
      "x": 1,
      "y": 3,
      "z": 3,
      "name": "Rock_Sandstone_White_Brick_Half",
      "rotation": 7
    },
    {
      "x": 1,
      "y": 4,
      "z": 3,
      "name": "Rock_Sandstone_White_Brick_Half",
      "rotation": 7
    },
    {
      "x": 1,
      "y": 5,
      "z": 3,
      "name": "Rock_Sandstone_White_Brick_Stairs",
      "rotation": 9
    },
    {
      "x": 1,
      "y": 6,
      "z": 3,
      "name": "Rock_Sandstone_White_Brick_Decorative"
    },
    {
      "x": 1,
      "y": 7,
      "z": 3,
      "name": "Rock_Sandstone_White_Brick_Decorative"
    },
    {
      "x": 1,
      "y": 8,
      "z": 3,
      "name": "Rock_Sandstone_White_Brick_Smooth_Half"
    },
    {
      "x": 1,
      "y": 0,
      "z": 4,
      "name": "Soil_Dirt"
    },
    {
      "x": 1,
      "y": 1,
      "z": 4,
      "name": "Rock_Sandstone_White"
    },
    {
      "x": 1,
      "y": 2,
      "z": 4,
      "name": "Rock_Sandstone_White_Brick_Half",
      "rotation": 7
    },
    {
      "x": 1,
      "y": 6,
      "z": 4,
      "name": "Rock_Sandstone_White_Brick_Stairs",
      "rotation": 10
    },
    {
      "x": 1,
      "y": 7,
      "z": 4,
      "name": "Rock_Sandstone_White_Brick_Stairs",
      "rotation": 10
    },
    {
      "x": 1,
      "y": 0,
      "z": 5,
      "name": "Soil_Dirt"
    },
    {
      "x": 1,
      "y": 1,
      "z": 5,
      "name": "Rock_Sandstone_White"
    },
    {
      "x": 1,
      "y": 2,
      "z": 5,
      "name": "Rock_Sandstone_White_Brick_Smooth_Half",
      "rotation": 7
    },
    {
      "x": 1,
      "y": 0,
      "z": 6,
      "name": "Soil_Dirt"
    },
    {
      "x": 1,
      "y": 1,
      "z": 6,
      "name": "Rock_Sandstone_White_Brick_Smooth"
    },
    {
      "x": 1,
      "y": 0,
      "z": 7,
      "name": "Soil_Dirt"
    },
    {
      "x": 1,
      "y": 1,
      "z": 7,
      "name": "Soil_Grass"
    },
    {
      "x": 2,
      "y": 0,
      "z": -6,
      "name": "Soil_Dirt"
    },
    {
      "x": 2,
      "y": 1,
      "z": -6,
      "name": "Soil_Grass"
    },
    {
      "x": 2,
      "y": 0,
      "z": -5,
      "name": "Soil_Dirt"
    },
    {
      "x": 2,
      "y": 1,
      "z": -5,
      "name": "Soil_Grass"
    },
    {
      "x": 2,
      "y": 2,
      "z": -5,
      "name": "Rock_Sandstone_White_Brick_Smooth_Half",
      "rotation": 6
    },
    {
      "x": 2,
      "y": 0,
      "z": -4,
      "name": "Soil_Dirt"
    },
    {
      "x": 2,
      "y": 1,
      "z": -4,
      "name": "Soil_Grass"
    },
    {
      "x": 2,
      "y": 2,
      "z": -4,
      "name": "Soil_Grass"
    },
    {
      "x": 2,
      "y": 3,
      "z": -4,
      "name": "Plant_Flower_Tall_Purple"
    },
    {
      "x": 2,
      "y": 0,
      "z": -3,
      "name": "Soil_Dirt"
    },
    {
      "x": 2,
      "y": 1,
      "z": -3,
      "name": "Soil_Grass"
    },
    {
      "x": 2,
      "y": 2,
      "z": -3,
      "name": "Soil_Grass"
    },
    {
      "x": 2,
      "y": 3,
      "z": -3,
      "name": "Rock_Sandstone_White_Brick_Half",
      "rotation": 6
    },
    {
      "x": 2,
      "y": 4,
      "z": -3,
      "name": "Rock_Sandstone_White_Brick_Half",
      "rotation": 6
    },
    {
      "x": 2,
      "y": 5,
      "z": -3,
      "name": "Rock_Sandstone_White_Brick_Half",
      "rotation": 6
    },
    {
      "x": 2,
      "y": 6,
      "z": -3,
      "name": "Rock_Sandstone_White_Brick_Stairs",
      "rotation": 8
    },
    {
      "x": 2,
      "y": 7,
      "z": -3,
      "name": "Rock_Sandstone_White_Brick_Stairs",
      "rotation": 8
    },
    {
      "x": 2,
      "y": 0,
      "z": -2,
      "name": "Soil_Dirt"
    },
    {
      "x": 2,
      "y": 1,
      "z": -2,
      "name": "Soil_Grass"
    },
    {
      "x": 2,
      "y": 2,
      "z": -2,
      "name": "Rock_Sandstone_White_Brick_Smooth"
    },
    {
      "x": 2,
      "y": 3,
      "z": -2,
      "name": "Rock_Sandstone_White_Brick_Ornate"
    },
    {
      "x": 2,
      "y": 4,
      "z": -2,
      "name": "Rock_Sandstone_White_Brick"
    },
    {
      "x": 2,
      "y": 5,
      "z": -2,
      "name": "Rock_Sandstone_White_Brick"
    },
    {
      "x": 2,
      "y": 6,
      "z": -2,
      "name": "Rock_Sandstone_White_Brick"
    },
    {
      "x": 2,
      "y": 7,
      "z": -2,
      "name": "Rock_Sandstone_White_Brick_Decorative"
    },
    {
      "x": 2,
      "y": 8,
      "z": -2,
      "name": "Rock_Sandstone_White_Brick_Smooth_Half"
    },
    {
      "x": 2,
      "y": 0,
      "z": -1,
      "name": "Rock_Sandstone_White_Brick_Smooth"
    },
    {
      "x": 2,
      "y": 1,
      "z": -1,
      "name": "*Rock_Sandstone_White_Brick_Stairs_State_Definitions_Inverted_Corner_Right"
    },
    {
      "x": 2,
      "y": 2,
      "z": -1,
      "name": "Rock_Sandstone_White_Brick_Half",
      "rotation": 4
    },
    {
      "x": 2,
      "y": 3,
      "z": -1,
      "name": "Rock_Sandstone_White_Brick_Half",
      "rotation": 4
    },
    {
      "x": 2,
      "y": 4,
      "z": -1,
      "name": "Rock_Sandstone_White_Brick_Half",
      "rotation": 4
    },
    {
      "x": 2,
      "y": 5,
      "z": -1,
      "name": "Rock_Sandstone_White_Brick_Stairs",
      "rotation": 10
    },
    {
      "x": 2,
      "y": 6,
      "z": -1,
      "name": "Rock_Sandstone_White_Brick_Decorative"
    },
    {
      "x": 2,
      "y": 7,
      "z": -1,
      "name": "Rock_Sandstone_White_Brick_Decorative"
    },
    {
      "x": 2,
      "y": 8,
      "z": -1,
      "name": "Rock_Sandstone_White_Brick_Smooth_Half"
    },
    {
      "x": 2,
      "y": 0,
      "z": 0,
      "name": "Rock_Sandstone_White_Brick_Smooth"
    },
    {
      "x": 2,
      "y": 1,
      "z": 0,
      "name": "Rock_Sandstone_White_Brick_Stairs",
      "rotation": 3
    },
    {
      "x": 2,
      "y": 6,
      "z": 0,
      "name": "Rock_Sandstone_White_Brick_Decorative"
    },
    {
      "x": 2,
      "y": 7,
      "z": 0,
      "name": "Rock_Sandstone_White_Brick_Decorative"
    },
    {
      "x": 2,
      "y": 8,
      "z": 0,
      "name": "Rock_Sandstone_White_Brick_Smooth_Half"
    },
    {
      "x": 2,
      "y": 0,
      "z": 1,
      "name": "Rock_Sandstone_White_Brick_Smooth"
    },
    {
      "x": 2,
      "y": 1,
      "z": 1,
      "name": "Rock_Sandstone_White_Brick_Stairs",
      "rotation": 3
    },
    {
      "x": 2,
      "y": 6,
      "z": 1,
      "name": "Rock_Sandstone_White_Brick_Decorative"
    },
    {
      "x": 2,
      "y": 7,
      "z": 1,
      "name": "Rock_Sandstone_White_Brick_Decorative"
    },
    {
      "x": 2,
      "y": 8,
      "z": 1,
      "name": "Rock_Sandstone_White_Brick_Smooth_Half"
    },
    {
      "x": 2,
      "y": 0,
      "z": 2,
      "name": "Rock_Sandstone_White_Brick_Smooth"
    },
    {
      "x": 2,
      "y": 1,
      "z": 2,
      "name": "*Rock_Sandstone_White_Brick_Stairs_State_Definitions_Inverted_Corner_Left",
      "rotation": 2
    },
    {
      "x": 2,
      "y": 2,
      "z": 2,
      "name": "Rock_Sandstone_White_Brick_Half",
      "rotation": 6
    },
    {
      "x": 2,
      "y": 3,
      "z": 2,
      "name": "Rock_Sandstone_White_Brick_Half",
      "rotation": 6
    },
    {
      "x": 2,
      "y": 4,
      "z": 2,
      "name": "Rock_Sandstone_White_Brick_Half",
      "rotation": 6
    },
    {
      "x": 2,
      "y": 5,
      "z": 2,
      "name": "Rock_Sandstone_White_Brick_Stairs",
      "rotation": 8
    },
    {
      "x": 2,
      "y": 6,
      "z": 2,
      "name": "Rock_Sandstone_White_Brick_Decorative"
    },
    {
      "x": 2,
      "y": 7,
      "z": 2,
      "name": "Rock_Sandstone_White_Brick_Decorative"
    },
    {
      "x": 2,
      "y": 8,
      "z": 2,
      "name": "Rock_Sandstone_White_Brick_Smooth_Half"
    },
    {
      "x": 2,
      "y": 0,
      "z": 3,
      "name": "Rock_Sandstone_White_Brick_Smooth"
    },
    {
      "x": 2,
      "y": 1,
      "z": 3,
      "name": "Soil_Grass"
    },
    {
      "x": 2,
      "y": 2,
      "z": 3,
      "name": "Rock_Sandstone_White_Brick_Smooth"
    },
    {
      "x": 2,
      "y": 3,
      "z": 3,
      "name": "Rock_Sandstone_White_Brick_Ornate"
    },
    {
      "x": 2,
      "y": 4,
      "z": 3,
      "name": "Rock_Sandstone_White_Brick"
    },
    {
      "x": 2,
      "y": 5,
      "z": 3,
      "name": "Rock_Sandstone_White_Brick"
    },
    {
      "x": 2,
      "y": 6,
      "z": 3,
      "name": "Rock_Sandstone_White_Brick"
    },
    {
      "x": 2,
      "y": 7,
      "z": 3,
      "name": "Rock_Sandstone_White_Brick_Decorative"
    },
    {
      "x": 2,
      "y": 8,
      "z": 3,
      "name": "Rock_Sandstone_White_Brick_Smooth_Half"
    },
    {
      "x": 2,
      "y": 0,
      "z": 4,
      "name": "Soil_Dirt"
    },
    {
      "x": 2,
      "y": 1,
      "z": 4,
      "name": "Soil_Grass"
    },
    {
      "x": 2,
      "y": 2,
      "z": 4,
      "name": "Soil_Grass"
    },
    {
      "x": 2,
      "y": 3,
      "z": 4,
      "name": "Rock_Sandstone_White_Brick_Half",
      "rotation": 4
    },
    {
      "x": 2,
      "y": 4,
      "z": 4,
      "name": "Rock_Sandstone_White_Brick_Half",
      "rotation": 4
    },
    {
      "x": 2,
      "y": 5,
      "z": 4,
      "name": "Rock_Sandstone_White_Brick_Half",
      "rotation": 4
    },
    {
      "x": 2,
      "y": 6,
      "z": 4,
      "name": "Rock_Sandstone_White_Brick_Stairs",
      "rotation": 10
    },
    {
      "x": 2,
      "y": 7,
      "z": 4,
      "name": "Rock_Sandstone_White_Brick_Stairs",
      "rotation": 10
    },
    {
      "x": 2,
      "y": 0,
      "z": 5,
      "name": "Soil_Dirt"
    },
    {
      "x": 2,
      "y": 1,
      "z": 5,
      "name": "Soil_Grass"
    },
    {
      "x": 2,
      "y": 2,
      "z": 5,
      "name": "Soil_Grass"
    },
    {
      "x": 2,
      "y": 3,
      "z": 5,
      "name": "Plant_Flower_Tall_Purple"
    },
    {
      "x": 2,
      "y": 0,
      "z": 6,
      "name": "Soil_Dirt"
    },
    {
      "x": 2,
      "y": 1,
      "z": 6,
      "name": "Soil_Grass"
    },
    {
      "x": 2,
      "y": 2,
      "z": 6,
      "name": "Rock_Sandstone_White_Brick_Smooth_Half",
      "rotation": 4
    },
    {
      "x": 2,
      "y": 0,
      "z": 7,
      "name": "Soil_Dirt"
    },
    {
      "x": 2,
      "y": 1,
      "z": 7,
      "name": "Soil_Grass"
    },
    {
      "x": 3,
      "y": 0,
      "z": -6,
      "name": "Soil_Dirt"
    },
    {
      "x": 3,
      "y": 1,
      "z": -6,
      "name": "Soil_Grass"
    },
    {
      "x": 3,
      "y": 0,
      "z": -5,
      "name": "Soil_Dirt"
    },
    {
      "x": 3,
      "y": 1,
      "z": -5,
      "name": "Soil_Grass"
    },
    {
      "x": 3,
      "y": 2,
      "z": -5,
      "name": "Rock_Sandstone_White_Brick_Smooth_Half",
      "rotation": 6
    },
    {
      "x": 3,
      "y": 0,
      "z": -4,
      "name": "Soil_Dirt"
    },
    {
      "x": 3,
      "y": 1,
      "z": -4,
      "name": "Soil_Grass"
    },
    {
      "x": 3,
      "y": 2,
      "z": -4,
      "name": "Soil_Grass"
    },
    {
      "x": 3,
      "y": 3,
      "z": -4,
      "name": "Plant_Flower_Tall_Purple"
    },
    {
      "x": 3,
      "y": 0,
      "z": -3,
      "name": "Soil_Dirt"
    },
    {
      "x": 3,
      "y": 1,
      "z": -3,
      "name": "Soil_Grass"
    },
    {
      "x": 3,
      "y": 2,
      "z": -3,
      "name": "Soil_Grass"
    },
    {
      "x": 3,
      "y": 3,
      "z": -3,
      "name": "Rock_Sandstone_White_Brick_Smooth"
    },
    {
      "x": 3,
      "y": 4,
      "z": -3,
      "name": "Furniture_Village_Brazier"
    },
    {
      "x": 3,
      "y": 6,
      "z": -3,
      "name": "*Rock_Sandstone_White_Brick_Stairs_State_Definitions_Corner_Left",
      "rotation": 8
    },
    {
      "x": 3,
      "y": 7,
      "z": -3,
      "name": "*Rock_Sandstone_White_Brick_Stairs_State_Definitions_Corner_Right",
      "rotation": 11
    },
    {
      "x": 3,
      "y": 0,
      "z": -2,
      "name": "Soil_Dirt"
    },
    {
      "x": 3,
      "y": 1,
      "z": -2,
      "name": "Soil_Grass"
    },
    {
      "x": 3,
      "y": 2,
      "z": -2,
      "name": "Soil_Grass"
    },
    {
      "x": 3,
      "y": 3,
      "z": -2,
      "name": "Rock_Sandstone_White_Brick_Half",
      "rotation": 5
    },
    {
      "x": 3,
      "y": 4,
      "z": -2,
      "name": "Rock_Sandstone_White_Brick_Half",
      "rotation": 5
    },
    {
      "x": 3,
      "y": 5,
      "z": -2,
      "name": "Rock_Sandstone_White_Brick_Half",
      "rotation": 5
    },
    {
      "x": 3,
      "y": 6,
      "z": -2,
      "name": "Rock_Sandstone_White_Brick_Stairs",
      "rotation": 11
    },
    {
      "x": 3,
      "y": 7,
      "z": -2,
      "name": "Rock_Sandstone_White_Brick_Stairs",
      "rotation": 11
    },
    {
      "x": 3,
      "y": 0,
      "z": -1,
      "name": "Soil_Dirt"
    },
    {
      "x": 3,
      "y": 1,
      "z": -1,
      "name": "Rock_Sandstone_White"
    },
    {
      "x": 3,
      "y": 2,
      "z": -1,
      "name": "Rock_Sandstone_White_Brick_Half",
      "rotation": 4
    },
    {
      "x": 3,
      "y": 6,
      "z": -1,
      "name": "Rock_Sandstone_White_Brick_Stairs",
      "rotation": 11
    },
    {
      "x": 3,
      "y": 7,
      "z": -1,
      "name": "Rock_Sandstone_White_Brick_Stairs",
      "rotation": 11
    },
    {
      "x": 3,
      "y": 0,
      "z": 0,
      "name": "Soil_Dirt"
    },
    {
      "x": 3,
      "y": 1,
      "z": 0,
      "name": "Rock_Sandstone_White"
    },
    {
      "x": 3,
      "y": 6,
      "z": 0,
      "name": "Rock_Sandstone_White_Brick_Stairs",
      "rotation": 11
    },
    {
      "x": 3,
      "y": 7,
      "z": 0,
      "name": "Rock_Sandstone_White_Brick_Stairs",
      "rotation": 11
    },
    {
      "x": 3,
      "y": 0,
      "z": 1,
      "name": "Soil_Dirt"
    },
    {
      "x": 3,
      "y": 1,
      "z": 1,
      "name": "Rock_Sandstone_White"
    },
    {
      "x": 3,
      "y": 6,
      "z": 1,
      "name": "Rock_Sandstone_White_Brick_Stairs",
      "rotation": 11
    },
    {
      "x": 3,
      "y": 7,
      "z": 1,
      "name": "Rock_Sandstone_White_Brick_Stairs",
      "rotation": 11
    },
    {
      "x": 3,
      "y": 0,
      "z": 2,
      "name": "Soil_Dirt"
    },
    {
      "x": 3,
      "y": 1,
      "z": 2,
      "name": "Rock_Sandstone_White"
    },
    {
      "x": 3,
      "y": 2,
      "z": 2,
      "name": "Rock_Sandstone_White_Brick_Half",
      "rotation": 6
    },
    {
      "x": 3,
      "y": 6,
      "z": 2,
      "name": "Rock_Sandstone_White_Brick_Stairs",
      "rotation": 11
    },
    {
      "x": 3,
      "y": 7,
      "z": 2,
      "name": "Rock_Sandstone_White_Brick_Stairs",
      "rotation": 11
    },
    {
      "x": 3,
      "y": 0,
      "z": 3,
      "name": "Soil_Dirt"
    },
    {
      "x": 3,
      "y": 1,
      "z": 3,
      "name": "Soil_Grass"
    },
    {
      "x": 3,
      "y": 2,
      "z": 3,
      "name": "Soil_Grass"
    },
    {
      "x": 3,
      "y": 3,
      "z": 3,
      "name": "Rock_Sandstone_White_Brick_Half",
      "rotation": 5
    },
    {
      "x": 3,
      "y": 4,
      "z": 3,
      "name": "Rock_Sandstone_White_Brick_Half",
      "rotation": 5
    },
    {
      "x": 3,
      "y": 5,
      "z": 3,
      "name": "Rock_Sandstone_White_Brick_Half",
      "rotation": 5
    },
    {
      "x": 3,
      "y": 6,
      "z": 3,
      "name": "Rock_Sandstone_White_Brick_Stairs",
      "rotation": 11
    },
    {
      "x": 3,
      "y": 7,
      "z": 3,
      "name": "Rock_Sandstone_White_Brick_Stairs",
      "rotation": 11
    },
    {
      "x": 3,
      "y": 0,
      "z": 4,
      "name": "Soil_Dirt"
    },
    {
      "x": 3,
      "y": 1,
      "z": 4,
      "name": "Soil_Grass"
    },
    {
      "x": 3,
      "y": 2,
      "z": 4,
      "name": "Soil_Grass"
    },
    {
      "x": 3,
      "y": 3,
      "z": 4,
      "name": "Rock_Sandstone_White_Brick_Smooth"
    },
    {
      "x": 3,
      "y": 4,
      "z": 4,
      "name": "Furniture_Village_Brazier"
    },
    {
      "x": 3,
      "y": 6,
      "z": 4,
      "name": "*Rock_Sandstone_White_Brick_Stairs_State_Definitions_Corner_Left",
      "rotation": 11
    },
    {
      "x": 3,
      "y": 7,
      "z": 4,
      "name": "*Rock_Sandstone_White_Brick_Stairs_State_Definitions_Corner_Left",
      "rotation": 11
    },
    {
      "x": 3,
      "y": 0,
      "z": 5,
      "name": "Soil_Dirt"
    },
    {
      "x": 3,
      "y": 1,
      "z": 5,
      "name": "Soil_Grass"
    },
    {
      "x": 3,
      "y": 2,
      "z": 5,
      "name": "Soil_Grass"
    },
    {
      "x": 3,
      "y": 3,
      "z": 5,
      "name": "Plant_Flower_Tall_Purple"
    },
    {
      "x": 3,
      "y": 0,
      "z": 6,
      "name": "Soil_Dirt"
    },
    {
      "x": 3,
      "y": 1,
      "z": 6,
      "name": "Soil_Grass"
    },
    {
      "x": 3,
      "y": 2,
      "z": 6,
      "name": "Rock_Sandstone_White_Brick_Smooth_Half",
      "rotation": 4
    },
    {
      "x": 3,
      "y": 0,
      "z": 7,
      "name": "Soil_Dirt"
    },
    {
      "x": 3,
      "y": 1,
      "z": 7,
      "name": "Soil_Grass"
    },
    {
      "x": 4,
      "y": 0,
      "z": -6,
      "name": "Soil_Dirt"
    },
    {
      "x": 4,
      "y": 1,
      "z": -6,
      "name": "Soil_Grass"
    },
    {
      "x": 4,
      "y": 0,
      "z": -5,
      "name": "Soil_Dirt"
    },
    {
      "x": 4,
      "y": 1,
      "z": -5,
      "name": "Soil_Grass"
    },
    {
      "x": 4,
      "y": 2,
      "z": -5,
      "name": "Rock_Sandstone_White_Brick_Smooth_Half",
      "rotation": 6
    },
    {
      "x": 4,
      "y": 0,
      "z": -4,
      "name": "Soil_Dirt"
    },
    {
      "x": 4,
      "y": 1,
      "z": -4,
      "name": "Soil_Grass"
    },
    {
      "x": 4,
      "y": 2,
      "z": -4,
      "name": "Soil_Grass"
    },
    {
      "x": 4,
      "y": 3,
      "z": -4,
      "name": "Plant_Flower_Tall_Purple"
    },
    {
      "x": 4,
      "y": 0,
      "z": -3,
      "name": "Soil_Dirt"
    },
    {
      "x": 4,
      "y": 1,
      "z": -3,
      "name": "Soil_Grass"
    },
    {
      "x": 4,
      "y": 2,
      "z": -3,
      "name": "Soil_Grass"
    },
    {
      "x": 4,
      "y": 3,
      "z": -3,
      "name": "Plant_Flower_Tall_Purple"
    },
    {
      "x": 4,
      "y": 0,
      "z": -2,
      "name": "Soil_Dirt"
    },
    {
      "x": 4,
      "y": 1,
      "z": -2,
      "name": "Soil_Grass"
    },
    {
      "x": 4,
      "y": 2,
      "z": -2,
      "name": "Soil_Grass"
    },
    {
      "x": 4,
      "y": 3,
      "z": -2,
      "name": "Plant_Flower_Tall_Purple"
    },
    {
      "x": 4,
      "y": 0,
      "z": -1,
      "name": "Soil_Dirt"
    },
    {
      "x": 4,
      "y": 1,
      "z": -1,
      "name": "Rock_Sandstone_White"
    },
    {
      "x": 4,
      "y": 2,
      "z": -1,
      "name": "Rock_Sandstone_White_Brick_Smooth_Half",
      "rotation": 4
    },
    {
      "x": 4,
      "y": 0,
      "z": 0,
      "name": "Soil_Dirt"
    },
    {
      "x": 4,
      "y": 1,
      "z": 0,
      "name": "Rock_Sandstone_White"
    },
    {
      "x": 4,
      "y": 0,
      "z": 1,
      "name": "Soil_Dirt"
    },
    {
      "x": 4,
      "y": 1,
      "z": 1,
      "name": "Rock_Sandstone_White"
    },
    {
      "x": 4,
      "y": 0,
      "z": 2,
      "name": "Soil_Dirt"
    },
    {
      "x": 4,
      "y": 1,
      "z": 2,
      "name": "Rock_Sandstone_White"
    },
    {
      "x": 4,
      "y": 2,
      "z": 2,
      "name": "Rock_Sandstone_White_Brick_Smooth_Half",
      "rotation": 6
    },
    {
      "x": 4,
      "y": 0,
      "z": 3,
      "name": "Soil_Dirt"
    },
    {
      "x": 4,
      "y": 1,
      "z": 3,
      "name": "Soil_Grass"
    },
    {
      "x": 4,
      "y": 2,
      "z": 3,
      "name": "Soil_Grass"
    },
    {
      "x": 4,
      "y": 3,
      "z": 3,
      "name": "Plant_Flower_Tall_Purple"
    },
    {
      "x": 4,
      "y": 0,
      "z": 4,
      "name": "Soil_Dirt"
    },
    {
      "x": 4,
      "y": 1,
      "z": 4,
      "name": "Soil_Grass"
    },
    {
      "x": 4,
      "y": 2,
      "z": 4,
      "name": "Soil_Grass"
    },
    {
      "x": 4,
      "y": 3,
      "z": 4,
      "name": "Plant_Flower_Tall_Purple"
    },
    {
      "x": 4,
      "y": 0,
      "z": 5,
      "name": "Soil_Dirt"
    },
    {
      "x": 4,
      "y": 1,
      "z": 5,
      "name": "Soil_Grass"
    },
    {
      "x": 4,
      "y": 2,
      "z": 5,
      "name": "Soil_Grass"
    },
    {
      "x": 4,
      "y": 3,
      "z": 5,
      "name": "Plant_Flower_Tall_Purple"
    },
    {
      "x": 4,
      "y": 0,
      "z": 6,
      "name": "Soil_Dirt"
    },
    {
      "x": 4,
      "y": 1,
      "z": 6,
      "name": "Soil_Grass"
    },
    {
      "x": 4,
      "y": 2,
      "z": 6,
      "name": "Rock_Sandstone_White_Brick_Smooth_Half",
      "rotation": 4
    },
    {
      "x": 4,
      "y": 0,
      "z": 7,
      "name": "Soil_Dirt"
    },
    {
      "x": 4,
      "y": 1,
      "z": 7,
      "name": "Soil_Grass"
    },
    {
      "x": 5,
      "y": 0,
      "z": -6,
      "name": "Soil_Dirt"
    },
    {
      "x": 5,
      "y": 1,
      "z": -6,
      "name": "Soil_Grass"
    },
    {
      "x": 5,
      "y": 0,
      "z": -5,
      "name": "Soil_Dirt"
    },
    {
      "x": 5,
      "y": 1,
      "z": -5,
      "name": "Soil_Grass"
    },
    {
      "x": 5,
      "y": 0,
      "z": -4,
      "name": "Soil_Dirt"
    },
    {
      "x": 5,
      "y": 1,
      "z": -4,
      "name": "Soil_Grass"
    },
    {
      "x": 5,
      "y": 2,
      "z": -4,
      "name": "Rock_Sandstone_White_Brick_Smooth_Half",
      "rotation": 5
    },
    {
      "x": 5,
      "y": 0,
      "z": -3,
      "name": "Soil_Dirt"
    },
    {
      "x": 5,
      "y": 1,
      "z": -3,
      "name": "Soil_Grass"
    },
    {
      "x": 5,
      "y": 2,
      "z": -3,
      "name": "Rock_Sandstone_White_Brick_Smooth_Half",
      "rotation": 5
    },
    {
      "x": 5,
      "y": 0,
      "z": -2,
      "name": "Soil_Dirt"
    },
    {
      "x": 5,
      "y": 1,
      "z": -2,
      "name": "Soil_Grass"
    },
    {
      "x": 5,
      "y": 2,
      "z": -2,
      "name": "Rock_Sandstone_White_Brick_Smooth_Half",
      "rotation": 5
    },
    {
      "x": 5,
      "y": 0,
      "z": -1,
      "name": "Soil_Dirt"
    },
    {
      "x": 5,
      "y": 1,
      "z": -1,
      "name": "Rock_Sandstone_White_Brick_Smooth"
    },
    {
      "x": 5,
      "y": 0,
      "z": 0,
      "name": "Soil_Dirt"
    },
    {
      "x": 5,
      "y": 1,
      "z": 0,
      "name": "Rock_Sandstone_White_Brick_Smooth"
    },
    {
      "x": 5,
      "y": 0,
      "z": 1,
      "name": "Soil_Dirt"
    },
    {
      "x": 5,
      "y": 1,
      "z": 1,
      "name": "Rock_Sandstone_White_Brick_Smooth"
    },
    {
      "x": 5,
      "y": 0,
      "z": 2,
      "name": "Soil_Dirt"
    },
    {
      "x": 5,
      "y": 1,
      "z": 2,
      "name": "Rock_Sandstone_White_Brick_Smooth"
    },
    {
      "x": 5,
      "y": 0,
      "z": 3,
      "name": "Soil_Dirt"
    },
    {
      "x": 5,
      "y": 1,
      "z": 3,
      "name": "Soil_Grass"
    },
    {
      "x": 5,
      "y": 2,
      "z": 3,
      "name": "Rock_Sandstone_White_Brick_Smooth_Half",
      "rotation": 5
    },
    {
      "x": 5,
      "y": 0,
      "z": 4,
      "name": "Soil_Dirt"
    },
    {
      "x": 5,
      "y": 1,
      "z": 4,
      "name": "Soil_Grass"
    },
    {
      "x": 5,
      "y": 2,
      "z": 4,
      "name": "Rock_Sandstone_White_Brick_Smooth_Half",
      "rotation": 5
    },
    {
      "x": 5,
      "y": 0,
      "z": 5,
      "name": "Soil_Dirt"
    },
    {
      "x": 5,
      "y": 1,
      "z": 5,
      "name": "Soil_Grass"
    },
    {
      "x": 5,
      "y": 2,
      "z": 5,
      "name": "Rock_Sandstone_White_Brick_Smooth_Half",
      "rotation": 5
    },
    {
      "x": 5,
      "y": 0,
      "z": 6,
      "name": "Soil_Dirt"
    },
    {
      "x": 5,
      "y": 1,
      "z": 6,
      "name": "Soil_Grass"
    },
    {
      "x": 5,
      "y": 0,
      "z": 7,
      "name": "Soil_Dirt"
    },
    {
      "x": 5,
      "y": 1,
      "z": 7,
      "name": "Soil_Grass"
    },
    {
      "x": 6,
      "y": 0,
      "z": -6,
      "name": "Soil_Dirt"
    },
    {
      "x": 6,
      "y": 1,
      "z": -6,
      "name": "Soil_Grass"
    },
    {
      "x": 6,
      "y": 0,
      "z": -5,
      "name": "Soil_Dirt"
    },
    {
      "x": 6,
      "y": 1,
      "z": -5,
      "name": "Soil_Grass"
    },
    {
      "x": 6,
      "y": 0,
      "z": -4,
      "name": "Soil_Dirt"
    },
    {
      "x": 6,
      "y": 1,
      "z": -4,
      "name": "Soil_Grass"
    },
    {
      "x": 6,
      "y": 0,
      "z": -3,
      "name": "Soil_Dirt"
    },
    {
      "x": 6,
      "y": 1,
      "z": -3,
      "name": "Soil_Grass"
    },
    {
      "x": 6,
      "y": 0,
      "z": -2,
      "name": "Soil_Dirt"
    },
    {
      "x": 6,
      "y": 1,
      "z": -2,
      "name": "Soil_Grass"
    },
    {
      "x": 6,
      "y": 0,
      "z": -1,
      "name": "Soil_Dirt"
    },
    {
      "x": 6,
      "y": 1,
      "z": -1,
      "name": "Soil_Grass"
    },
    {
      "x": 6,
      "y": 0,
      "z": 0,
      "name": "Soil_Dirt"
    },
    {
      "x": 6,
      "y": 1,
      "z": 0,
      "name": "Soil_Grass"
    },
    {
      "x": 6,
      "y": 0,
      "z": 1,
      "name": "Soil_Dirt"
    },
    {
      "x": 6,
      "y": 1,
      "z": 1,
      "name": "Soil_Grass"
    },
    {
      "x": 6,
      "y": 0,
      "z": 2,
      "name": "Soil_Dirt"
    },
    {
      "x": 6,
      "y": 1,
      "z": 2,
      "name": "Soil_Grass"
    },
    {
      "x": 6,
      "y": 0,
      "z": 3,
      "name": "Soil_Dirt"
    },
    {
      "x": 6,
      "y": 1,
      "z": 3,
      "name": "Soil_Grass"
    },
    {
      "x": 6,
      "y": 0,
      "z": 4,
      "name": "Soil_Dirt"
    },
    {
      "x": 6,
      "y": 1,
      "z": 4,
      "name": "Soil_Grass"
    },
    {
      "x": 6,
      "y": 0,
      "z": 5,
      "name": "Soil_Dirt"
    },
    {
      "x": 6,
      "y": 1,
      "z": 5,
      "name": "Soil_Grass"
    },
    {
      "x": 6,
      "y": 0,
      "z": 6,
      "name": "Soil_Dirt"
    },
    {
      "x": 6,
      "y": 1,
      "z": 6,
      "name": "Soil_Grass"
    },
    {
      "x": 6,
      "y": 0,
      "z": 7,
      "name": "Soil_Dirt"
    },
    {
      "x": 6,
      "y": 1,
      "z": 7,
      "name": "Soil_Grass"
    }
  ],
  "fluids": [
    {
      "x": -6,
      "y": 0,
      "z": -6,
      "name": "Empty",
      "level": 0
    },
    {
      "x": -6,
      "y": 1,
      "z": -6,
      "name": "Empty",
      "level": 0
    },
    {
      "x": -6,
      "y": 0,
      "z": -5,
      "name": "Empty",
      "level": 0
    },
    {
      "x": -6,
      "y": 1,
      "z": -5,
      "name": "Empty",
      "level": 0
    },
    {
      "x": -6,
      "y": 0,
      "z": -4,
      "name": "Empty",
      "level": 0
    },
    {
      "x": -6,
      "y": 1,
      "z": -4,
      "name": "Empty",
      "level": 0
    },
    {
      "x": -6,
      "y": 2,
      "z": -4,
      "name": "Empty",
      "level": 0
    },
    {
      "x": -6,
      "y": 0,
      "z": -3,
      "name": "Empty",
      "level": 0
    },
    {
      "x": -6,
      "y": 1,
      "z": -3,
      "name": "Empty",
      "level": 0
    },
    {
      "x": -6,
      "y": 2,
      "z": -3,
      "name": "Empty",
      "level": 0
    },
    {
      "x": -6,
      "y": 0,
      "z": -2,
      "name": "Empty",
      "level": 0
    },
    {
      "x": -6,
      "y": 1,
      "z": -2,
      "name": "Empty",
      "level": 0
    },
    {
      "x": -6,
      "y": 2,
      "z": -2,
      "name": "Empty",
      "level": 0
    },
    {
      "x": -6,
      "y": 0,
      "z": -1,
      "name": "Empty",
      "level": 0
    },
    {
      "x": -6,
      "y": 1,
      "z": -1,
      "name": "Empty",
      "level": 0
    },
    {
      "x": -6,
      "y": 0,
      "z": 0,
      "name": "Empty",
      "level": 0
    },
    {
      "x": -6,
      "y": 1,
      "z": 0,
      "name": "Empty",
      "level": 0
    },
    {
      "x": -6,
      "y": 0,
      "z": 1,
      "name": "Empty",
      "level": 0
    },
    {
      "x": -6,
      "y": 1,
      "z": 1,
      "name": "Empty",
      "level": 0
    },
    {
      "x": -6,
      "y": 0,
      "z": 2,
      "name": "Empty",
      "level": 0
    },
    {
      "x": -6,
      "y": 1,
      "z": 2,
      "name": "Empty",
      "level": 0
    },
    {
      "x": -6,
      "y": 0,
      "z": 3,
      "name": "Empty",
      "level": 0
    },
    {
      "x": -6,
      "y": 1,
      "z": 3,
      "name": "Empty",
      "level": 0
    },
    {
      "x": -6,
      "y": 2,
      "z": 3,
      "name": "Empty",
      "level": 0
    },
    {
      "x": -6,
      "y": 0,
      "z": 4,
      "name": "Empty",
      "level": 0
    },
    {
      "x": -6,
      "y": 1,
      "z": 4,
      "name": "Empty",
      "level": 0
    },
    {
      "x": -6,
      "y": 2,
      "z": 4,
      "name": "Empty",
      "level": 0
    },
    {
      "x": -6,
      "y": 0,
      "z": 5,
      "name": "Empty",
      "level": 0
    },
    {
      "x": -6,
      "y": 1,
      "z": 5,
      "name": "Empty",
      "level": 0
    },
    {
      "x": -6,
      "y": 2,
      "z": 5,
      "name": "Empty",
      "level": 0
    },
    {
      "x": -6,
      "y": 0,
      "z": 6,
      "name": "Empty",
      "level": 0
    },
    {
      "x": -6,
      "y": 1,
      "z": 6,
      "name": "Empty",
      "level": 0
    },
    {
      "x": -6,
      "y": 0,
      "z": 7,
      "name": "Empty",
      "level": 0
    },
    {
      "x": -6,
      "y": 1,
      "z": 7,
      "name": "Empty",
      "level": 0
    },
    {
      "x": -5,
      "y": 0,
      "z": -6,
      "name": "Empty",
      "level": 0
    },
    {
      "x": -5,
      "y": 1,
      "z": -6,
      "name": "Empty",
      "level": 0
    },
    {
      "x": -5,
      "y": 0,
      "z": -5,
      "name": "Empty",
      "level": 0
    },
    {
      "x": -5,
      "y": 1,
      "z": -5,
      "name": "Empty",
      "level": 0
    },
    {
      "x": -5,
      "y": 2,
      "z": -5,
      "name": "Empty",
      "level": 0
    },
    {
      "x": -5,
      "y": 0,
      "z": -4,
      "name": "Empty",
      "level": 0
    },
    {
      "x": -5,
      "y": 1,
      "z": -4,
      "name": "Empty",
      "level": 0
    },
    {
      "x": -5,
      "y": 2,
      "z": -4,
      "name": "Empty",
      "level": 0
    },
    {
      "x": -5,
      "y": 3,
      "z": -4,
      "name": "Empty",
      "level": 0
    },
    {
      "x": -5,
      "y": 0,
      "z": -3,
      "name": "Empty",
      "level": 0
    },
    {
      "x": -5,
      "y": 1,
      "z": -3,
      "name": "Empty",
      "level": 0
    },
    {
      "x": -5,
      "y": 2,
      "z": -3,
      "name": "Empty",
      "level": 0
    },
    {
      "x": -5,
      "y": 3,
      "z": -3,
      "name": "Empty",
      "level": 0
    },
    {
      "x": -5,
      "y": 0,
      "z": -2,
      "name": "Empty",
      "level": 0
    },
    {
      "x": -5,
      "y": 1,
      "z": -2,
      "name": "Empty",
      "level": 0
    },
    {
      "x": -5,
      "y": 2,
      "z": -2,
      "name": "Empty",
      "level": 0
    },
    {
      "x": -5,
      "y": 3,
      "z": -2,
      "name": "Empty",
      "level": 0
    },
    {
      "x": -5,
      "y": 0,
      "z": -1,
      "name": "Empty",
      "level": 0
    },
    {
      "x": -5,
      "y": 1,
      "z": -1,
      "name": "Empty",
      "level": 0
    },
    {
      "x": -5,
      "y": 2,
      "z": -1,
      "name": "Empty",
      "level": 0
    },
    {
      "x": -5,
      "y": 0,
      "z": 0,
      "name": "Empty",
      "level": 0
    },
    {
      "x": -5,
      "y": 1,
      "z": 0,
      "name": "Empty",
      "level": 0
    },
    {
      "x": -5,
      "y": 0,
      "z": 1,
      "name": "Empty",
      "level": 0
    },
    {
      "x": -5,
      "y": 1,
      "z": 1,
      "name": "Empty",
      "level": 0
    },
    {
      "x": -5,
      "y": 0,
      "z": 2,
      "name": "Empty",
      "level": 0
    },
    {
      "x": -5,
      "y": 1,
      "z": 2,
      "name": "Empty",
      "level": 0
    },
    {
      "x": -5,
      "y": 2,
      "z": 2,
      "name": "Empty",
      "level": 0
    },
    {
      "x": -5,
      "y": 0,
      "z": 3,
      "name": "Empty",
      "level": 0
    },
    {
      "x": -5,
      "y": 1,
      "z": 3,
      "name": "Empty",
      "level": 0
    },
    {
      "x": -5,
      "y": 2,
      "z": 3,
      "name": "Empty",
      "level": 0
    },
    {
      "x": -5,
      "y": 3,
      "z": 3,
      "name": "Empty",
      "level": 0
    },
    {
      "x": -5,
      "y": 0,
      "z": 4,
      "name": "Empty",
      "level": 0
    },
    {
      "x": -5,
      "y": 1,
      "z": 4,
      "name": "Empty",
      "level": 0
    },
    {
      "x": -5,
      "y": 2,
      "z": 4,
      "name": "Empty",
      "level": 0
    },
    {
      "x": -5,
      "y": 3,
      "z": 4,
      "name": "Empty",
      "level": 0
    },
    {
      "x": -5,
      "y": 0,
      "z": 5,
      "name": "Empty",
      "level": 0
    },
    {
      "x": -5,
      "y": 1,
      "z": 5,
      "name": "Empty",
      "level": 0
    },
    {
      "x": -5,
      "y": 2,
      "z": 5,
      "name": "Empty",
      "level": 0
    },
    {
      "x": -5,
      "y": 3,
      "z": 5,
      "name": "Empty",
      "level": 0
    },
    {
      "x": -5,
      "y": 0,
      "z": 6,
      "name": "Empty",
      "level": 0
    },
    {
      "x": -5,
      "y": 1,
      "z": 6,
      "name": "Empty",
      "level": 0
    },
    {
      "x": -5,
      "y": 2,
      "z": 6,
      "name": "Empty",
      "level": 0
    },
    {
      "x": -5,
      "y": 0,
      "z": 7,
      "name": "Empty",
      "level": 0
    },
    {
      "x": -5,
      "y": 1,
      "z": 7,
      "name": "Empty",
      "level": 0
    },
    {
      "x": -4,
      "y": 0,
      "z": -6,
      "name": "Empty",
      "level": 0
    },
    {
      "x": -4,
      "y": 1,
      "z": -6,
      "name": "Empty",
      "level": 0
    },
    {
      "x": -4,
      "y": 0,
      "z": -5,
      "name": "Empty",
      "level": 0
    },
    {
      "x": -4,
      "y": 1,
      "z": -5,
      "name": "Empty",
      "level": 0
    },
    {
      "x": -4,
      "y": 2,
      "z": -5,
      "name": "Empty",
      "level": 0
    },
    {
      "x": -4,
      "y": 0,
      "z": -4,
      "name": "Empty",
      "level": 0
    },
    {
      "x": -4,
      "y": 1,
      "z": -4,
      "name": "Empty",
      "level": 0
    },
    {
      "x": -4,
      "y": 2,
      "z": -4,
      "name": "Empty",
      "level": 0
    },
    {
      "x": -4,
      "y": 3,
      "z": -4,
      "name": "Empty",
      "level": 0
    },
    {
      "x": -4,
      "y": 0,
      "z": -3,
      "name": "Empty",
      "level": 0
    },
    {
      "x": -4,
      "y": 1,
      "z": -3,
      "name": "Empty",
      "level": 0
    },
    {
      "x": -4,
      "y": 2,
      "z": -3,
      "name": "Empty",
      "level": 0
    },
    {
      "x": -4,
      "y": 3,
      "z": -3,
      "name": "Empty",
      "level": 0
    },
    {
      "x": -4,
      "y": 4,
      "z": -3,
      "name": "Empty",
      "level": 0
    },
    {
      "x": -4,
      "y": 6,
      "z": -3,
      "name": "Empty",
      "level": 0
    },
    {
      "x": -4,
      "y": 7,
      "z": -3,
      "name": "Empty",
      "level": 0
    },
    {
      "x": -4,
      "y": 0,
      "z": -2,
      "name": "Empty",
      "level": 0
    },
    {
      "x": -4,
      "y": 1,
      "z": -2,
      "name": "Empty",
      "level": 0
    },
    {
      "x": -4,
      "y": 2,
      "z": -2,
      "name": "Empty",
      "level": 0
    },
    {
      "x": -4,
      "y": 3,
      "z": -2,
      "name": "Empty",
      "level": 0
    },
    {
      "x": -4,
      "y": 4,
      "z": -2,
      "name": "Empty",
      "level": 0
    },
    {
      "x": -4,
      "y": 5,
      "z": -2,
      "name": "Empty",
      "level": 0
    },
    {
      "x": -4,
      "y": 6,
      "z": -2,
      "name": "Empty",
      "level": 0
    },
    {
      "x": -4,
      "y": 7,
      "z": -2,
      "name": "Empty",
      "level": 0
    },
    {
      "x": -4,
      "y": 0,
      "z": -1,
      "name": "Empty",
      "level": 0
    },
    {
      "x": -4,
      "y": 1,
      "z": -1,
      "name": "Empty",
      "level": 0
    },
    {
      "x": -4,
      "y": 2,
      "z": -1,
      "name": "Empty",
      "level": 0
    },
    {
      "x": -4,
      "y": 6,
      "z": -1,
      "name": "Empty",
      "level": 0
    },
    {
      "x": -4,
      "y": 7,
      "z": -1,
      "name": "Empty",
      "level": 0
    },
    {
      "x": -4,
      "y": 0,
      "z": 0,
      "name": "Empty",
      "level": 0
    },
    {
      "x": -4,
      "y": 1,
      "z": 0,
      "name": "Empty",
      "level": 0
    },
    {
      "x": -4,
      "y": 6,
      "z": 0,
      "name": "Empty",
      "level": 0
    },
    {
      "x": -4,
      "y": 7,
      "z": 0,
      "name": "Empty",
      "level": 0
    },
    {
      "x": -4,
      "y": 0,
      "z": 1,
      "name": "Empty",
      "level": 0
    },
    {
      "x": -4,
      "y": 1,
      "z": 1,
      "name": "Empty",
      "level": 0
    },
    {
      "x": -4,
      "y": 6,
      "z": 1,
      "name": "Empty",
      "level": 0
    },
    {
      "x": -4,
      "y": 7,
      "z": 1,
      "name": "Empty",
      "level": 0
    },
    {
      "x": -4,
      "y": 0,
      "z": 2,
      "name": "Empty",
      "level": 0
    },
    {
      "x": -4,
      "y": 1,
      "z": 2,
      "name": "Empty",
      "level": 0
    },
    {
      "x": -4,
      "y": 2,
      "z": 2,
      "name": "Empty",
      "level": 0
    },
    {
      "x": -4,
      "y": 6,
      "z": 2,
      "name": "Empty",
      "level": 0
    },
    {
      "x": -4,
      "y": 7,
      "z": 2,
      "name": "Empty",
      "level": 0
    },
    {
      "x": -4,
      "y": 0,
      "z": 3,
      "name": "Empty",
      "level": 0
    },
    {
      "x": -4,
      "y": 1,
      "z": 3,
      "name": "Empty",
      "level": 0
    },
    {
      "x": -4,
      "y": 2,
      "z": 3,
      "name": "Empty",
      "level": 0
    },
    {
      "x": -4,
      "y": 3,
      "z": 3,
      "name": "Empty",
      "level": 0
    },
    {
      "x": -4,
      "y": 4,
      "z": 3,
      "name": "Empty",
      "level": 0
    },
    {
      "x": -4,
      "y": 5,
      "z": 3,
      "name": "Empty",
      "level": 0
    },
    {
      "x": -4,
      "y": 6,
      "z": 3,
      "name": "Empty",
      "level": 0
    },
    {
      "x": -4,
      "y": 7,
      "z": 3,
      "name": "Empty",
      "level": 0
    },
    {
      "x": -4,
      "y": 0,
      "z": 4,
      "name": "Empty",
      "level": 0
    },
    {
      "x": -4,
      "y": 1,
      "z": 4,
      "name": "Empty",
      "level": 0
    },
    {
      "x": -4,
      "y": 2,
      "z": 4,
      "name": "Empty",
      "level": 0
    },
    {
      "x": -4,
      "y": 3,
      "z": 4,
      "name": "Empty",
      "level": 0
    },
    {
      "x": -4,
      "y": 4,
      "z": 4,
      "name": "Empty",
      "level": 0
    },
    {
      "x": -4,
      "y": 6,
      "z": 4,
      "name": "Empty",
      "level": 0
    },
    {
      "x": -4,
      "y": 7,
      "z": 4,
      "name": "Empty",
      "level": 0
    },
    {
      "x": -4,
      "y": 0,
      "z": 5,
      "name": "Empty",
      "level": 0
    },
    {
      "x": -4,
      "y": 1,
      "z": 5,
      "name": "Empty",
      "level": 0
    },
    {
      "x": -4,
      "y": 2,
      "z": 5,
      "name": "Empty",
      "level": 0
    },
    {
      "x": -4,
      "y": 3,
      "z": 5,
      "name": "Empty",
      "level": 0
    },
    {
      "x": -4,
      "y": 0,
      "z": 6,
      "name": "Empty",
      "level": 0
    },
    {
      "x": -4,
      "y": 1,
      "z": 6,
      "name": "Empty",
      "level": 0
    },
    {
      "x": -4,
      "y": 2,
      "z": 6,
      "name": "Empty",
      "level": 0
    },
    {
      "x": -4,
      "y": 0,
      "z": 7,
      "name": "Empty",
      "level": 0
    },
    {
      "x": -4,
      "y": 1,
      "z": 7,
      "name": "Empty",
      "level": 0
    },
    {
      "x": -3,
      "y": 0,
      "z": -6,
      "name": "Empty",
      "level": 0
    },
    {
      "x": -3,
      "y": 1,
      "z": -6,
      "name": "Empty",
      "level": 0
    },
    {
      "x": -3,
      "y": 0,
      "z": -5,
      "name": "Empty",
      "level": 0
    },
    {
      "x": -3,
      "y": 1,
      "z": -5,
      "name": "Empty",
      "level": 0
    },
    {
      "x": -3,
      "y": 2,
      "z": -5,
      "name": "Empty",
      "level": 0
    },
    {
      "x": -3,
      "y": 0,
      "z": -4,
      "name": "Empty",
      "level": 0
    },
    {
      "x": -3,
      "y": 1,
      "z": -4,
      "name": "Empty",
      "level": 0
    },
    {
      "x": -3,
      "y": 2,
      "z": -4,
      "name": "Empty",
      "level": 0
    },
    {
      "x": -3,
      "y": 3,
      "z": -4,
      "name": "Empty",
      "level": 0
    },
    {
      "x": -3,
      "y": 0,
      "z": -3,
      "name": "Empty",
      "level": 0
    },
    {
      "x": -3,
      "y": 1,
      "z": -3,
      "name": "Empty",
      "level": 0
    },
    {
      "x": -3,
      "y": 2,
      "z": -3,
      "name": "Empty",
      "level": 0
    },
    {
      "x": -3,
      "y": 3,
      "z": -3,
      "name": "Empty",
      "level": 0
    },
    {
      "x": -3,
      "y": 4,
      "z": -3,
      "name": "Empty",
      "level": 0
    },
    {
      "x": -3,
      "y": 5,
      "z": -3,
      "name": "Empty",
      "level": 0
    },
    {
      "x": -3,
      "y": 6,
      "z": -3,
      "name": "Empty",
      "level": 0
    },
    {
      "x": -3,
      "y": 7,
      "z": -3,
      "name": "Empty",
      "level": 0
    },
    {
      "x": -3,
      "y": 0,
      "z": -2,
      "name": "Empty",
      "level": 0
    },
    {
      "x": -3,
      "y": 1,
      "z": -2,
      "name": "Empty",
      "level": 0
    },
    {
      "x": -3,
      "y": 2,
      "z": -2,
      "name": "Empty",
      "level": 0
    },
    {
      "x": -3,
      "y": 3,
      "z": -2,
      "name": "Empty",
      "level": 0
    },
    {
      "x": -3,
      "y": 4,
      "z": -2,
      "name": "Empty",
      "level": 0
    },
    {
      "x": -3,
      "y": 5,
      "z": -2,
      "name": "Empty",
      "level": 0
    },
    {
      "x": -3,
      "y": 6,
      "z": -2,
      "name": "Empty",
      "level": 0
    },
    {
      "x": -3,
      "y": 7,
      "z": -2,
      "name": "Empty",
      "level": 0
    },
    {
      "x": -3,
      "y": 8,
      "z": -2,
      "name": "Empty",
      "level": 0
    },
    {
      "x": -3,
      "y": 0,
      "z": -1,
      "name": "Empty",
      "level": 0
    },
    {
      "x": -3,
      "y": 1,
      "z": -1,
      "name": "Empty",
      "level": 0
    },
    {
      "x": -3,
      "y": 2,
      "z": -1,
      "name": "Empty",
      "level": 0
    },
    {
      "x": -3,
      "y": 3,
      "z": -1,
      "name": "Empty",
      "level": 0
    },
    {
      "x": -3,
      "y": 4,
      "z": -1,
      "name": "Empty",
      "level": 0
    },
    {
      "x": -3,
      "y": 5,
      "z": -1,
      "name": "Empty",
      "level": 0
    },
    {
      "x": -3,
      "y": 6,
      "z": -1,
      "name": "Empty",
      "level": 0
    },
    {
      "x": -3,
      "y": 7,
      "z": -1,
      "name": "Empty",
      "level": 0
    },
    {
      "x": -3,
      "y": 8,
      "z": -1,
      "name": "Empty",
      "level": 0
    },
    {
      "x": -3,
      "y": 0,
      "z": 0,
      "name": "Empty",
      "level": 0
    },
    {
      "x": -3,
      "y": 1,
      "z": 0,
      "name": "Empty",
      "level": 0
    },
    {
      "x": -3,
      "y": 6,
      "z": 0,
      "name": "Empty",
      "level": 0
    },
    {
      "x": -3,
      "y": 7,
      "z": 0,
      "name": "Empty",
      "level": 0
    },
    {
      "x": -3,
      "y": 8,
      "z": 0,
      "name": "Empty",
      "level": 0
    },
    {
      "x": -3,
      "y": 0,
      "z": 1,
      "name": "Empty",
      "level": 0
    },
    {
      "x": -3,
      "y": 1,
      "z": 1,
      "name": "Empty",
      "level": 0
    },
    {
      "x": -3,
      "y": 6,
      "z": 1,
      "name": "Empty",
      "level": 0
    },
    {
      "x": -3,
      "y": 7,
      "z": 1,
      "name": "Empty",
      "level": 0
    },
    {
      "x": -3,
      "y": 8,
      "z": 1,
      "name": "Empty",
      "level": 0
    },
    {
      "x": -3,
      "y": 0,
      "z": 2,
      "name": "Empty",
      "level": 0
    },
    {
      "x": -3,
      "y": 1,
      "z": 2,
      "name": "Empty",
      "level": 0
    },
    {
      "x": -3,
      "y": 2,
      "z": 2,
      "name": "Empty",
      "level": 0
    },
    {
      "x": -3,
      "y": 3,
      "z": 2,
      "name": "Empty",
      "level": 0
    },
    {
      "x": -3,
      "y": 4,
      "z": 2,
      "name": "Empty",
      "level": 0
    },
    {
      "x": -3,
      "y": 5,
      "z": 2,
      "name": "Empty",
      "level": 0
    },
    {
      "x": -3,
      "y": 6,
      "z": 2,
      "name": "Empty",
      "level": 0
    },
    {
      "x": -3,
      "y": 7,
      "z": 2,
      "name": "Empty",
      "level": 0
    },
    {
      "x": -3,
      "y": 8,
      "z": 2,
      "name": "Empty",
      "level": 0
    },
    {
      "x": -3,
      "y": 0,
      "z": 3,
      "name": "Empty",
      "level": 0
    },
    {
      "x": -3,
      "y": 1,
      "z": 3,
      "name": "Empty",
      "level": 0
    },
    {
      "x": -3,
      "y": 2,
      "z": 3,
      "name": "Empty",
      "level": 0
    },
    {
      "x": -3,
      "y": 3,
      "z": 3,
      "name": "Empty",
      "level": 0
    },
    {
      "x": -3,
      "y": 4,
      "z": 3,
      "name": "Empty",
      "level": 0
    },
    {
      "x": -3,
      "y": 5,
      "z": 3,
      "name": "Empty",
      "level": 0
    },
    {
      "x": -3,
      "y": 6,
      "z": 3,
      "name": "Empty",
      "level": 0
    },
    {
      "x": -3,
      "y": 7,
      "z": 3,
      "name": "Empty",
      "level": 0
    },
    {
      "x": -3,
      "y": 8,
      "z": 3,
      "name": "Empty",
      "level": 0
    },
    {
      "x": -3,
      "y": 0,
      "z": 4,
      "name": "Empty",
      "level": 0
    },
    {
      "x": -3,
      "y": 1,
      "z": 4,
      "name": "Empty",
      "level": 0
    },
    {
      "x": -3,
      "y": 2,
      "z": 4,
      "name": "Empty",
      "level": 0
    },
    {
      "x": -3,
      "y": 3,
      "z": 4,
      "name": "Empty",
      "level": 0
    },
    {
      "x": -3,
      "y": 4,
      "z": 4,
      "name": "Empty",
      "level": 0
    },
    {
      "x": -3,
      "y": 5,
      "z": 4,
      "name": "Empty",
      "level": 0
    },
    {
      "x": -3,
      "y": 6,
      "z": 4,
      "name": "Empty",
      "level": 0
    },
    {
      "x": -3,
      "y": 7,
      "z": 4,
      "name": "Empty",
      "level": 0
    },
    {
      "x": -3,
      "y": 0,
      "z": 5,
      "name": "Empty",
      "level": 0
    },
    {
      "x": -3,
      "y": 1,
      "z": 5,
      "name": "Empty",
      "level": 0
    },
    {
      "x": -3,
      "y": 2,
      "z": 5,
      "name": "Empty",
      "level": 0
    },
    {
      "x": -3,
      "y": 3,
      "z": 5,
      "name": "Empty",
      "level": 0
    },
    {
      "x": -3,
      "y": 0,
      "z": 6,
      "name": "Empty",
      "level": 0
    },
    {
      "x": -3,
      "y": 1,
      "z": 6,
      "name": "Empty",
      "level": 0
    },
    {
      "x": -3,
      "y": 2,
      "z": 6,
      "name": "Empty",
      "level": 0
    },
    {
      "x": -3,
      "y": 0,
      "z": 7,
      "name": "Empty",
      "level": 0
    },
    {
      "x": -3,
      "y": 1,
      "z": 7,
      "name": "Empty",
      "level": 0
    },
    {
      "x": -2,
      "y": 0,
      "z": -6,
      "name": "Empty",
      "level": 0
    },
    {
      "x": -2,
      "y": 1,
      "z": -6,
      "name": "Empty",
      "level": 0
    },
    {
      "x": -2,
      "y": 0,
      "z": -5,
      "name": "Empty",
      "level": 0
    },
    {
      "x": -2,
      "y": 1,
      "z": -5,
      "name": "Empty",
      "level": 0
    },
    {
      "x": -2,
      "y": 0,
      "z": -4,
      "name": "Empty",
      "level": 0
    },
    {
      "x": -2,
      "y": 1,
      "z": -4,
      "name": "Empty",
      "level": 0
    },
    {
      "x": -2,
      "y": 2,
      "z": -4,
      "name": "Empty",
      "level": 0
    },
    {
      "x": -2,
      "y": 0,
      "z": -3,
      "name": "Empty",
      "level": 0
    },
    {
      "x": -2,
      "y": 1,
      "z": -3,
      "name": "Empty",
      "level": 0
    },
    {
      "x": -2,
      "y": 2,
      "z": -3,
      "name": "Empty",
      "level": 0
    },
    {
      "x": -2,
      "y": 6,
      "z": -3,
      "name": "Empty",
      "level": 0
    },
    {
      "x": -2,
      "y": 7,
      "z": -3,
      "name": "Empty",
      "level": 0
    },
    {
      "x": -2,
      "y": 0,
      "z": -2,
      "name": "Empty",
      "level": 0
    },
    {
      "x": -2,
      "y": 1,
      "z": -2,
      "name": "Empty",
      "level": 0
    },
    {
      "x": -2,
      "y": 2,
      "z": -2,
      "name": "Empty",
      "level": 0
    },
    {
      "x": -2,
      "y": 3,
      "z": -2,
      "name": "Empty",
      "level": 0
    },
    {
      "x": -2,
      "y": 4,
      "z": -2,
      "name": "Empty",
      "level": 0
    },
    {
      "x": -2,
      "y": 5,
      "z": -2,
      "name": "Empty",
      "level": 0
    },
    {
      "x": -2,
      "y": 6,
      "z": -2,
      "name": "Empty",
      "level": 0
    },
    {
      "x": -2,
      "y": 7,
      "z": -2,
      "name": "Empty",
      "level": 0
    },
    {
      "x": -2,
      "y": 8,
      "z": -2,
      "name": "Empty",
      "level": 0
    },
    {
      "x": -2,
      "y": 0,
      "z": -1,
      "name": "Empty",
      "level": 0
    },
    {
      "x": -2,
      "y": 6,
      "z": -1,
      "name": "Empty",
      "level": 0
    },
    {
      "x": -2,
      "y": 7,
      "z": -1,
      "name": "Empty",
      "level": 0
    },
    {
      "x": -2,
      "y": 0,
      "z": 0,
      "name": "Empty",
      "level": 0
    },
    {
      "x": -2,
      "y": 6,
      "z": 0,
      "name": "Empty",
      "level": 0
    },
    {
      "x": -2,
      "y": 7,
      "z": 0,
      "name": "Empty",
      "level": 0
    },
    {
      "x": -2,
      "y": 0,
      "z": 1,
      "name": "Empty",
      "level": 0
    },
    {
      "x": -2,
      "y": 6,
      "z": 1,
      "name": "Empty",
      "level": 0
    },
    {
      "x": -2,
      "y": 7,
      "z": 1,
      "name": "Empty",
      "level": 0
    },
    {
      "x": -2,
      "y": 0,
      "z": 2,
      "name": "Empty",
      "level": 0
    },
    {
      "x": -2,
      "y": 6,
      "z": 2,
      "name": "Empty",
      "level": 0
    },
    {
      "x": -2,
      "y": 7,
      "z": 2,
      "name": "Empty",
      "level": 0
    },
    {
      "x": -2,
      "y": 0,
      "z": 3,
      "name": "Empty",
      "level": 0
    },
    {
      "x": -2,
      "y": 1,
      "z": 3,
      "name": "Empty",
      "level": 0
    },
    {
      "x": -2,
      "y": 2,
      "z": 3,
      "name": "Empty",
      "level": 0
    },
    {
      "x": -2,
      "y": 3,
      "z": 3,
      "name": "Empty",
      "level": 0
    },
    {
      "x": -2,
      "y": 4,
      "z": 3,
      "name": "Empty",
      "level": 0
    },
    {
      "x": -2,
      "y": 5,
      "z": 3,
      "name": "Empty",
      "level": 0
    },
    {
      "x": -2,
      "y": 6,
      "z": 3,
      "name": "Empty",
      "level": 0
    },
    {
      "x": -2,
      "y": 7,
      "z": 3,
      "name": "Empty",
      "level": 0
    },
    {
      "x": -2,
      "y": 8,
      "z": 3,
      "name": "Empty",
      "level": 0
    },
    {
      "x": -2,
      "y": 0,
      "z": 4,
      "name": "Empty",
      "level": 0
    },
    {
      "x": -2,
      "y": 1,
      "z": 4,
      "name": "Empty",
      "level": 0
    },
    {
      "x": -2,
      "y": 2,
      "z": 4,
      "name": "Empty",
      "level": 0
    },
    {
      "x": -2,
      "y": 6,
      "z": 4,
      "name": "Empty",
      "level": 0
    },
    {
      "x": -2,
      "y": 7,
      "z": 4,
      "name": "Empty",
      "level": 0
    },
    {
      "x": -2,
      "y": 0,
      "z": 5,
      "name": "Empty",
      "level": 0
    },
    {
      "x": -2,
      "y": 1,
      "z": 5,
      "name": "Empty",
      "level": 0
    },
    {
      "x": -2,
      "y": 2,
      "z": 5,
      "name": "Empty",
      "level": 0
    },
    {
      "x": -2,
      "y": 0,
      "z": 6,
      "name": "Empty",
      "level": 0
    },
    {
      "x": -2,
      "y": 1,
      "z": 6,
      "name": "Empty",
      "level": 0
    },
    {
      "x": -2,
      "y": 0,
      "z": 7,
      "name": "Empty",
      "level": 0
    },
    {
      "x": -2,
      "y": 1,
      "z": 7,
      "name": "Empty",
      "level": 0
    },
    {
      "x": -1,
      "y": 0,
      "z": -6,
      "name": "Empty",
      "level": 0
    },
    {
      "x": -1,
      "y": 1,
      "z": -6,
      "name": "Empty",
      "level": 0
    },
    {
      "x": -1,
      "y": 0,
      "z": -5,
      "name": "Empty",
      "level": 0
    },
    {
      "x": -1,
      "y": 1,
      "z": -5,
      "name": "Empty",
      "level": 0
    },
    {
      "x": -1,
      "y": 0,
      "z": -4,
      "name": "Empty",
      "level": 0
    },
    {
      "x": -1,
      "y": 1,
      "z": -4,
      "name": "Empty",
      "level": 0
    },
    {
      "x": -1,
      "y": 0,
      "z": -3,
      "name": "Empty",
      "level": 0
    },
    {
      "x": -1,
      "y": 1,
      "z": -3,
      "name": "Empty",
      "level": 0
    },
    {
      "x": -1,
      "y": 6,
      "z": -3,
      "name": "Empty",
      "level": 0
    },
    {
      "x": -1,
      "y": 7,
      "z": -3,
      "name": "Empty",
      "level": 0
    },
    {
      "x": -1,
      "y": 0,
      "z": -2,
      "name": "Empty",
      "level": 0
    },
    {
      "x": -1,
      "y": 1,
      "z": -2,
      "name": "Empty",
      "level": 0
    },
    {
      "x": -1,
      "y": 6,
      "z": -2,
      "name": "Empty",
      "level": 0
    },
    {
      "x": -1,
      "y": 7,
      "z": -2,
      "name": "Empty",
      "level": 0
    },
    {
      "x": -1,
      "y": 8,
      "z": -2,
      "name": "Empty",
      "level": 0
    },
    {
      "x": -1,
      "y": 0,
      "z": -1,
      "name": "Empty",
      "level": 0
    },
    {
      "x": -1,
      "y": 6,
      "z": -1,
      "name": "Empty",
      "level": 0
    },
    {
      "x": -1,
      "y": 7,
      "z": -1,
      "name": "Empty",
      "level": 0
    },
    {
      "x": -1,
      "y": 0,
      "z": 0,
      "name": "Empty",
      "level": 0
    },
    {
      "x": -1,
      "y": 6,
      "z": 0,
      "name": "Empty",
      "level": 0
    },
    {
      "x": -1,
      "y": 7,
      "z": 0,
      "name": "Empty",
      "level": 0
    },
    {
      "x": -1,
      "y": 0,
      "z": 1,
      "name": "Empty",
      "level": 0
    },
    {
      "x": -1,
      "y": 6,
      "z": 1,
      "name": "Empty",
      "level": 0
    },
    {
      "x": -1,
      "y": 7,
      "z": 1,
      "name": "Empty",
      "level": 0
    },
    {
      "x": -1,
      "y": 0,
      "z": 2,
      "name": "Empty",
      "level": 0
    },
    {
      "x": -1,
      "y": 6,
      "z": 2,
      "name": "Empty",
      "level": 0
    },
    {
      "x": -1,
      "y": 7,
      "z": 2,
      "name": "Empty",
      "level": 0
    },
    {
      "x": -1,
      "y": 0,
      "z": 3,
      "name": "Empty",
      "level": 0
    },
    {
      "x": -1,
      "y": 1,
      "z": 3,
      "name": "Empty",
      "level": 0
    },
    {
      "x": -1,
      "y": 6,
      "z": 3,
      "name": "Empty",
      "level": 0
    },
    {
      "x": -1,
      "y": 7,
      "z": 3,
      "name": "Empty",
      "level": 0
    },
    {
      "x": -1,
      "y": 8,
      "z": 3,
      "name": "Empty",
      "level": 0
    },
    {
      "x": -1,
      "y": 0,
      "z": 4,
      "name": "Empty",
      "level": 0
    },
    {
      "x": -1,
      "y": 1,
      "z": 4,
      "name": "Empty",
      "level": 0
    },
    {
      "x": -1,
      "y": 6,
      "z": 4,
      "name": "Empty",
      "level": 0
    },
    {
      "x": -1,
      "y": 7,
      "z": 4,
      "name": "Empty",
      "level": 0
    },
    {
      "x": -1,
      "y": 0,
      "z": 5,
      "name": "Empty",
      "level": 0
    },
    {
      "x": -1,
      "y": 1,
      "z": 5,
      "name": "Empty",
      "level": 0
    },
    {
      "x": -1,
      "y": 0,
      "z": 6,
      "name": "Empty",
      "level": 0
    },
    {
      "x": -1,
      "y": 1,
      "z": 6,
      "name": "Empty",
      "level": 0
    },
    {
      "x": -1,
      "y": 0,
      "z": 7,
      "name": "Empty",
      "level": 0
    },
    {
      "x": -1,
      "y": 1,
      "z": 7,
      "name": "Empty",
      "level": 0
    },
    {
      "x": 0,
      "y": 0,
      "z": -6,
      "name": "Empty",
      "level": 0
    },
    {
      "x": 0,
      "y": 1,
      "z": -6,
      "name": "Empty",
      "level": 0
    },
    {
      "x": 0,
      "y": 0,
      "z": -5,
      "name": "Empty",
      "level": 0
    },
    {
      "x": 0,
      "y": 1,
      "z": -5,
      "name": "Empty",
      "level": 0
    },
    {
      "x": 0,
      "y": 0,
      "z": -4,
      "name": "Empty",
      "level": 0
    },
    {
      "x": 0,
      "y": 1,
      "z": -4,
      "name": "Empty",
      "level": 0
    },
    {
      "x": 0,
      "y": 0,
      "z": -3,
      "name": "Empty",
      "level": 0
    },
    {
